Workbook

Sheet Planejamento
B1: | PROGRAMAÇÃO DA ESTAÇÃO REPRODUTIVA
AI2: Estação | AM2: Nasacimento | AS2: Desmama | AW2: Seca
B3: Programação da estação | E3: CALENDÁRIO REPRODUTIVO PROGRAMADO | AH3: =MONTH(AI3) -> 11 | AI3: =C6 -> 45597 | AJ3: =IF(AND(AI3>=$C$6,AI3<=$C$8),"Ok","Não") -> Ok | AL3: =MONTH(AM3) -> 8 | AM3: =C9 -> 45877 | AN3: =IF(AND(AM3>=$C$9,AM3<=$C$10),"Ok","Não") -> Ok | AR3: =MONTH(AS3) -> 3 | AS3: =C11 -> 46087 | AT3: =IF(AND(AS3>=$C$11,AS3<=$C$12),"Ok","Não") -> Ok | AV3: =MONTH(AW3) -> 4 | AW3: =C4 -> 45383 | AX3: =IF(AND(AW3>=$C$4,AW3<=$C$5),"Ok","Não") -> Ok
B4: Início da seca | C4: 45383 | E4: Meses | F4: J | G4: A | H4: S | I4: O | J4: N | K4: D | L4: J | M4: F | N4: M | O4: A | P4: M | Q4: J | AH4: =MONTH(AI4) -> 11 | AI4: =AI3+1 -> 45598 | AJ4: =IF(AND(AI4>=$C$6,AI4<=$C$8),"Ok","Não") -> Ok | AL4: =MONTH(AM4) -> 8 | AM4: =AM3+1 -> 45878 | AN4: =IF(AND(AM4>=$C$9,AM4<=$C$10),"Ok","Não") -> Ok | AR4: =MONTH(AS4) -> 3 | AS4: =AS3+1 -> 46088 | AT4: =IF(AND(AS4>=$C$11,AS4<=$C$12),"Ok","Não") -> Ok | AV4: =MONTH(AW4) -> 4 | AW4: =AW3+1 -> 45384 | AX4: =IF(AND(AW4>=$C$4,AW4<=$C$5),"Ok","Não") -> Ok
B5: Final da seca | C5: 45580 | E5: Chuva/seca | F5: =VLOOKUP(S6,$S$8:$W$19,5,0) -> Ok | G5: =VLOOKUP(T6,$S$8:$W$19,5,0) -> Ok | H5: =VLOOKUP(U6,$S$8:$W$19,5,0) -> Ok | I5: =VLOOKUP(V6,$S$8:$W$19,5,0) -> Ok | J5: =VLOOKUP(W6,$S$8:$W$19,5,0) -> Não | K5: =VLOOKUP(X6,$S$8:$W$19,5,0) -> Não | L5: =VLOOKUP(Y6,$S$8:$W$19,5,0) -> Não | M5: =VLOOKUP(Z6,$S$8:$W$19,5,0) -> Não | ... Q5: =VLOOKUP(AD6,$S$8:$W$19,5,0) -> Ok | AH5: =MONTH(AI5) -> 11 | AI5: =AI4+1 -> 45599 | AJ5: =IF(AND(AI5>=$C$6,AI5<=$C$8),"Ok","Não") -> Ok | AL5: =MONTH(AM5) -> 8 | AM5: =AM4+1 -> 45879 | AN5: =IF(AND(AM5>=$C$9,AM5<=$C$10),"Ok","Não") -> Ok | AR5: =MONTH(AS5) -> 3 | AS5: =AS4+1 -> 46089 | AT5: =IF(AND(AS5>=$C$11,AS5<=$C$12),"Ok","Não") -> Ok | AV5: =MONTH(AW5) -> 4 | AW5: =AW4+1 -> 45385 | AX5: =IF(AND(AW5>=$C$4,AW5<=$C$5),"Ok","Não") -> Ok
B6: Data de início da estação | C6: 45597 | E6: "Estação" | F6: =VLOOKUP(S6,$S$8:$T$19,2,0) -> Não | G6: =VLOOKUP(T6,$S$8:$T$19,2,0) -> Não | H6: =VLOOKUP(U6,$S$8:$T$19,2,0) -> Não | I6: =VLOOKUP(V6,$S$8:$T$19,2,0) -> Não | J6: =VLOOKUP(W6,$S$8:$T$19,2,0) -> Ok | K6: =VLOOKUP(X6,$S$8:$T$19,2,0) -> Ok | L6: =VLOOKUP(Y6,$S$8:$T$19,2,0) -> Ok | M6: =VLOOKUP(Z6,$S$8:$T$19,2,0) -> Não | ... Q6: =VLOOKUP(AD6,$S$8:$T$19,2,0) -> Não | S6: 7 | T6: 8 | U6: 9 | V6: 10 | W6: 11 | X6: 12 | Y6: 1 | Z6: 2 | AA6: 3 | AB6: 4 | AC6: 5 | AD6: 6 | AH6: =MONTH(AI6) -> 11 | AI6: =AI5+1 -> 45600 | AJ6: =IF(AND(AI6>=$C$6,AI6<=$C$8),"Ok","Não") -> Ok | AL6: =MONTH(AM6) -> 8 | AM6: =AM5+1 -> 45880 | AN6: =IF(AND(AM6>=$C$9,AM6<=$C$10),"Ok","Não") -> Ok | AR6: =MONTH(AS6) -> 3 | AS6: =AS5+1 -> 46090 | AT6: =IF(AND(AS6>=$C$11,AS6<=$C$12),"Ok","Não") -> Ok | AV6: =MONTH(AW6) -> 4 | AW6: =AW5+1 -> 45386 | AX6: =IF(AND(AW6>=$C$4,AW6<=$C$5),"Ok","Não") -> Ok
B7: Duração planejada (dias) | C7: 90 | E7: Nascimento | F7: =VLOOKUP(S6,$S$8:$V$19,3,0) -> Não | G7: =VLOOKUP(T6,$S$8:$V$19,3,0) -> Ok | H7: =VLOOKUP(U6,$S$8:$V$19,3,0) -> Ok | I7: =VLOOKUP(V6,$S$8:$V$19,3,0) -> Ok | J7: =VLOOKUP(W6,$S$8:$V$19,3,0) -> Ok | K7: =VLOOKUP(X6,$S$8:$V$19,3,0) -> Não | L7: =VLOOKUP(Y6,$S$8:$V$19,3,0) -> Não | M7: =VLOOKUP(Z6,$S$8:$V$19,3,0) -> Não | ... Q7: =VLOOKUP(AD6,$S$8:$V$19,3,0) -> Não | T7: Estação | U7: Nascimento | V7: Desmama | W7: Seca | AH7: =MONTH(AI7) -> 11 | AI7: =AI6+1 -> 45601 | AJ7: =IF(AND(AI7>=$C$6,AI7<=$C$8),"Ok","Não") -> Ok | AL7: =MONTH(AM7) -> 8 | AM7: =AM6+1 -> 45881 | AN7: =IF(AND(AM7>=$C$9,AM7<=$C$10),"Ok","Não") -> Ok | AR7: =MONTH(AS7) -> 3 | AS7: =AS6+1 -> 46091 | AT7: =IF(AND(AS7>=$C$11,AS7<=$C$12),"Ok","Não") -> Ok | AV7: =MONTH(AW7) -> 4 | AW7: =AW6+1 -> 45387 | AX7: =IF(AND(AW7>=$C$4,AW7<=$C$5),"Ok","Não") -> Ok
B8: Data final | C8: =C7+C6 -> 45687 | E8: Desmama | F8: =VLOOKUP(S6,$S$8:$V$19,4,0) -> Não | G8: =VLOOKUP(T6,$S$8:$V$19,4,0) -> Não | H8: =VLOOKUP(U6,$S$8:$V$19,4,0) -> Não | I8: =VLOOKUP(V6,$S$8:$V$19,4,0) -> Não | J8: =VLOOKUP(W6,$S$8:$V$19,4,0) -> Não | K8: =VLOOKUP(X6,$S$8:$V$19,4,0) -> Não | L8: =VLOOKUP(Y6,$S$8:$V$19,4,0) -> Não | M8: =VLOOKUP(Z6,$S$8:$V$19,4,0) -> Não | ... Q8: =VLOOKUP(AD6,$S$8:$V$19,4,0) -> Ok | S8: 1 | T8: =VLOOKUP(S8,$AH$3:$AJ$584,3,0) -> Ok | U8: =VLOOKUP(S8,$AL$3:$AN$584,3,0) -> Não | V8: =VLOOKUP(S8,$AR$3:$AT$584,3,0) -> Não | W8: =VLOOKUP(S8,$AV$3:$AX$584,3,0) -> Não | AH8: =MONTH(AI8) -> 11 | AI8: =AI7+1 -> 45602 | AJ8: =IF(AND(AI8>=$C$6,AI8<=$C$8),"Ok","Não") -> Ok | AL8: =MONTH(AM8) -> 8 | AM8: =AM7+1 -> 45882 | AN8: =IF(AND(AM8>=$C$9,AM8<=$C$10),"Ok","Não") -> Ok | AR8: =MONTH(AS8) -> 3 | AS8: =AS7+1 -> 46092 | AT8: =IF(AND(AS8>=$C$11,AS8<=$C$12),"Ok","Não") -> Ok | AV8: =MONTH(AW8) -> 4 | AW8: =AW7+1 -> 45388 | AX8: =IF(AND(AW8>=$C$4,AW8<=$C$5),"Ok","Não") -> Ok
B9: Início dos nascimentos | C9: =C6+280 -> 45877 | S9: 2 | T9: =VLOOKUP(S9,$AH$3:$AJ$584,3,0) -> Não | U9: =VLOOKUP(S9,$AL$3:$AN$584,3,0) -> Não | V9: =VLOOKUP(S9,$AR$3:$AT$584,3,0) -> Não | W9: =VLOOKUP(S9,$AV$3:$AX$584,3,0) -> Não | AH9: =MONTH(AI9) -> 11 | AI9: =AI8+1 -> 45603 | AJ9: =IF(AND(AI9>=$C$6,AI9<=$C$8),"Ok","Não") -> Ok | AL9: =MONTH(AM9) -> 8 | AM9: =AM8+1 -> 45883 | AN9: =IF(AND(AM9>=$C$9,AM9<=$C$10),"Ok","Não") -> Ok | AR9: =MONTH(AS9) -> 3 | AS9: =AS8+1 -> 46093 | AT9: =IF(AND(AS9>=$C$11,AS9<=$C$12),"Ok","Não") -> Ok | AV9: =MONTH(AW9) -> 4 | AW9: =AW8+1 -> 45389 | AX9: =IF(AND(AW9>=$C$4,AW9<=$C$5),"Ok","Não") -> Ok
B10: Final dos nascimentos | C10: =C9+C7 -> 45967 | S10: 3 | T10: =VLOOKUP(S10,$AH$3:$AJ$584,3,0) -> Não | U10: =VLOOKUP(S10,$AL$3:$AN$584,3,0) -> Não | V10: =VLOOKUP(S10,$AR$3:$AT$584,3,0) -> Ok | W10: =VLOOKUP(S10,$AV$3:$AX$584,3,0) -> Não | AH10: =MONTH(AI10) -> 11 | AI10: =AI9+1 -> 45604 | AJ10: =IF(AND(AI10>=$C$6,AI10<=$C$8),"Ok","Não") -> Ok | AL10: =MONTH(AM10) -> 8 | AM10: =AM9+1 -> 45884 | AN10: =IF(AND(AM10>=$C$9,AM10<=$C$10),"Ok","Não") -> Ok | AR10: =MONTH(AS10) -> 3 | AS10: =AS9+1 -> 46094 | AT10: =IF(AND(AS10>=$C$11,AS10<=$C$12),"Ok","Não") -> Ok | AV10: =MONTH(AW10) -> 4 | AW10: =AW9+1 -> 45390 | AX10: =IF(AND(AW10>=$C$4,AW10<=$C$5),"Ok","Não") -> Ok
B11: Início da desmama | C11: =C9+210 -> 46087 | S11: 4 | T11: =VLOOKUP(S11,$AH$3:$AJ$584,3,0) -> Não | U11: =VLOOKUP(S11,$AL$3:$AN$584,3,0) -> Não | V11: =VLOOKUP(S11,$AR$3:$AT$584,3,0) -> Ok | W11: =VLOOKUP(S11,$AV$3:$AX$584,3,0) -> Ok | AH11: =MONTH(AI11) -> 11 | AI11: =AI10+1 -> 45605 | AJ11: =IF(AND(AI11>=$C$6,AI11<=$C$8),"Ok","Não") -> Ok | AL11: =MONTH(AM11) -> 8 | AM11: =AM10+1 -> 45885 | AN11: =IF(AND(AM11>=$C$9,AM11<=$C$10),"Ok","Não") -> Ok | AR11: =MONTH(AS11) -> 3 | AS11: =AS10+1 -> 46095 | AT11: =IF(AND(AS11>=$C$11,AS11<=$C$12),"Ok","Não") -> Ok | AV11: =MONTH(AW11) -> 4 | AW11: =AW10+1 -> 45391 | AX11: =IF(AND(AW11>=$C$4,AW11<=$C$5),"Ok","Não") -> Ok
B12: Final da desmama | C12: =C10+210 -> 46177 | S12: 5 | T12: =VLOOKUP(S12,$AH$3:$AJ$584,3,0) -> Não | U12: =VLOOKUP(S12,$AL$3:$AN$584,3,0) -> Não | V12: =VLOOKUP(S12,$AR$3:$AT$584,3,0) -> Ok | W12: =VLOOKUP(S12,$AV$3:$AX$584,3,0) -> Ok | AH12: =MONTH(AI12) -> 11 | AI12: =AI11+1 -> 45606 | AJ12: =IF(AND(AI12>=$C$6,AI12<=$C$8),"Ok","Não") -> Ok | AL12: =MONTH(AM12) -> 8 | AM12: =AM11+1 -> 45886 | AN12: =IF(AND(AM12>=$C$9,AM12<=$C$10),"Ok","Não") -> Ok | AR12: =MONTH(AS12) -> 3 | AS12: =AS11+1 -> 46096 | AT12: =IF(AND(AS12>=$C$11,AS12<=$C$12),"Ok","Não") -> Ok | AV12: =MONTH(AW12) -> 4 | AW12: =AW11+1 -> 45392 | AX12: =IF(AND(AW12>=$C$4,AW12<=$C$5),"Ok","Não") -> Ok
B13: Dias até início da próxima estação | C13: =C6+365-C9 -> 85 | S13: 6 | T13: =VLOOKUP(S13,$AH$3:$AJ$584,3,0) -> Não | U13: =VLOOKUP(S13,$AL$3:$AN$584,3,0) -> Não | V13: =VLOOKUP(S13,$AR$3:$AT$584,3,0) -> Ok | W13: =VLOOKUP(S13,$AV$3:$AX$584,3,0) -> Ok | AH13: =MONTH(AI13) -> 11 | AI13: =AI12+1 -> 45607 | AJ13: =IF(AND(AI13>=$C$6,AI13<=$C$8),"Ok","Não") -> Ok | AL13: =MONTH(AM13) -> 8 | AM13: =AM12+1 -> 45887 | AN13: =IF(AND(AM13>=$C$9,AM13<=$C$10),"Ok","Não") -> Ok | AR13: =MONTH(AS13) -> 3 | AS13: =AS12+1 -> 46097 | AT13: =IF(AND(AS13>=$C$11,AS13<=$C$12),"Ok","Não") -> Ok | AV13: =MONTH(AW13) -> 4 | AW13: =AW12+1 -> 45393 | AX13: =IF(AND(AW13>=$C$4,AW13<=$C$5),"Ok","Não") -> Ok
B14: Início da próxima estação | C14: =C13+C9 -> 45962 | S14: 7 | T14: =VLOOKUP(S14,$AH$3:$AJ$584,3,0) -> Não | U14: =VLOOKUP(S14,$AL$3:$AN$584,3,0) -> Não | V14: =VLOOKUP(S14,$AR$3:$AT$584,3,0) -> Não | W14: =VLOOKUP(S14,$AV$3:$AX$584,3,0) -> Ok | AH14: =MONTH(AI14) -> 11 | AI14: =AI13+1 -> 45608 | AJ14: =IF(AND(AI14>=$C$6,AI14<=$C$8),"Ok","Não") -> Ok | AL14: =MONTH(AM14) -> 8 | AM14: =AM13+1 -> 45888 | AN14: =IF(AND(AM14>=$C$9,AM14<=$C$10),"Ok","Não") -> Ok | AR14: =MONTH(AS14) -> 3 | AS14: =AS13+1 -> 46098 | AT14: =IF(AND(AS14>=$C$11,AS14<=$C$12),"Ok","Não") -> Ok | AV14: =MONTH(AW14) -> 4 | AW14: =AW13+1 -> 45394 | AX14: =IF(AND(AW14>=$C$4,AW14<=$C$5),"Ok","Não") -> Ok
S15: 8 | T15: =VLOOKUP(S15,$AH$3:$AJ$584,3,0) -> Não | U15: =VLOOKUP(S15,$AL$3:$AN$584,3,0) -> Ok | V15: =VLOOKUP(S15,$AR$3:$AT$584,3,0) -> Não | W15: =VLOOKUP(S15,$AV$3:$AX$584,3,0) -> Ok | AH15: =MONTH(AI15) -> 11 | AI15: =AI14+1 -> 45609 | AJ15: =IF(AND(AI15>=$C$6,AI15<=$C$8),"Ok","Não") -> Ok | AL15: =MONTH(AM15) -> 8 | AM15: =AM14+1 -> 45889 | AN15: =IF(AND(AM15>=$C$9,AM15<=$C$10),"Ok","Não") -> Ok | AR15: =MONTH(AS15) -> 3 | AS15: =AS14+1 -> 46099 | AT15: =IF(AND(AS15>=$C$11,AS15<=$C$12),"Ok","Não") -> Ok | AV15: =MONTH(AW15) -> 4 | AW15: =AW14+1 -> 45395 | AX15: =IF(AND(AW15>=$C$4,AW15<=$C$5),"Ok","Não") -> Ok
S16: 9 | T16: =VLOOKUP(S16,$AH$3:$AJ$584,3,0) -> Não | U16: =VLOOKUP(S16,$AL$3:$AN$584,3,0) -> Ok | V16: =VLOOKUP(S16,$AR$3:$AT$584,3,0) -> Não | W16: =VLOOKUP(S16,$AV$3:$AX$584,3,0) -> Ok | AH16: =MONTH(AI16) -> 11 | AI16: =AI15+1 -> 45610 | AJ16: =IF(AND(AI16>=$C$6,AI16<=$C$8),"Ok","Não") -> Ok | AL16: =MONTH(AM16) -> 8 | AM16: =AM15+1 -> 45890 | AN16: =IF(AND(AM16>=$C$9,AM16<=$C$10),"Ok","Não") -> Ok | AR16: =MONTH(AS16) -> 3 | AS16: =AS15+1 -> 46100 | AT16: =IF(AND(AS16>=$C$11,AS16<=$C$12),"Ok","Não") -> Ok | AV16: =MONTH(AW16) -> 4 | AW16: =AW15+1 -> 45396 | AX16: =IF(AND(AW16>=$C$4,AW16<=$C$5),"Ok","Não") -> Ok
S17: 10 | T17: =VLOOKUP(S17,$AH$3:$AJ$584,3,0) -> Não | U17: =VLOOKUP(S17,$AL$3:$AN$584,3,0) -> Ok | V17: =VLOOKUP(S17,$AR$3:$AT$584,3,0) -> Não | W17: =VLOOKUP(S17,$AV$3:$AX$584,3,0) -> Ok | AH17: =MONTH(AI17) -> 11 | AI17: =AI16+1 -> 45611 | AJ17: =IF(AND(AI17>=$C$6,AI17<=$C$8),"Ok","Não") -> Ok | AL17: =MONTH(AM17) -> 8 | AM17: =AM16+1 -> 45891 | AN17: =IF(AND(AM17>=$C$9,AM17<=$C$10),"Ok","Não") -> Ok | AR17: =MONTH(AS17) -> 3 | AS17: =AS16+1 -> 46101 | AT17: =IF(AND(AS17>=$C$11,AS17<=$C$12),"Ok","Não") -> Ok | AV17: =MONTH(AW17) -> 4 | AW17: =AW16+1 -> 45397 | AX17: =IF(AND(AW17>=$C$4,AW17<=$C$5),"Ok","Não") -> Ok
S18: 11 | T18: =VLOOKUP(S18,$AH$3:$AJ$584,3,0) -> Ok | U18: =VLOOKUP(S18,$AL$3:$AN$584,3,0) -> Ok | V18: =VLOOKUP(S18,$AR$3:$AT$584,3,0) -> Não | W18: =VLOOKUP(S18,$AV$3:$AX$584,3,0) -> Não | AH18: =MONTH(AI18) -> 11 | AI18: =AI17+1 -> 45612 | AJ18: =IF(AND(AI18>=$C$6,AI18<=$C$8),"Ok","Não") -> Ok | AL18: =MONTH(AM18) -> 8 | AM18: =AM17+1 -> 45892 | AN18: =IF(AND(AM18>=$C$9,AM18<=$C$10),"Ok","Não") -> Ok | AR18: =MONTH(AS18) -> 3 | AS18: =AS17+1 -> 46102 | AT18: =IF(AND(AS18>=$C$11,AS18<=$C$12),"Ok","Não") -> Ok | AV18: =MONTH(AW18) -> 4 | AW18: =AW17+1 -> 45398 | AX18: =IF(AND(AW18>=$C$4,AW18<=$C$5),"Ok","Não") -> Ok
S19: 12 | T19: =VLOOKUP(S19,$AH$3:$AJ$584,3,0) -> Ok | U19: =VLOOKUP(S19,$AL$3:$AN$584,3,0) -> Não | V19: =VLOOKUP(S19,$AR$3:$AT$584,3,0) -> Não | W19: =VLOOKUP(S19,$AV$3:$AX$584,3,0) -> Não | AH19: =MONTH(AI19) -> 11 | AI19: =AI18+1 -> 45613 | AJ19: =IF(AND(AI19>=$C$6,AI19<=$C$8),"Ok","Não") -> Ok | AL19: =MONTH(AM19) -> 8 | AM19: =AM18+1 -> 45893 | AN19: =IF(AND(AM19>=$C$9,AM19<=$C$10),"Ok","Não") -> Ok | AR19: =MONTH(AS19) -> 3 | AS19: =AS18+1 -> 46103 | AT19: =IF(AND(AS19>=$C$11,AS19<=$C$12),"Ok","Não") -> Ok | AV19: =MONTH(AW19) -> 4 | AW19: =AW18+1 -> 45399 | AX19: =IF(AND(AW19>=$C$4,AW19<=$C$5),"Ok","Não") -> Ok
AH20: =MONTH(AI20) -> 11 | AI20: =AI19+1 -> 45614 | AJ20: =IF(AND(AI20>=$C$6,AI20<=$C$8),"Ok","Não") -> Ok | AL20: =MONTH(AM20) -> 8 | AM20: =AM19+1 -> 45894 | AN20: =IF(AND(AM20>=$C$9,AM20<=$C$10),"Ok","Não") -> Ok | AR20: =MONTH(AS20) -> 3 | AS20: =AS19+1 -> 46104 | AT20: =IF(AND(AS20>=$C$11,AS20<=$C$12),"Ok","Não") -> Ok | AV20: =MONTH(AW20) -> 4 | AW20: =AW19+1 -> 45400 | AX20: =IF(AND(AW20>=$C$4,AW20<=$C$5),"Ok","Não") -> Ok
AH21: =MONTH(AI21) -> 11 | AI21: =AI20+1 -> 45615 | AJ21: =IF(AND(AI21>=$C$6,AI21<=$C$8),"Ok","Não") -> Ok | AL21: =MONTH(AM21) -> 8 | AM21: =AM20+1 -> 45895 | AN21: =IF(AND(AM21>=$C$9,AM21<=$C$10),"Ok","Não") -> Ok | AR21: =MONTH(AS21) -> 3 | AS21: =AS20+1 -> 46105 | AT21: =IF(AND(AS21>=$C$11,AS21<=$C$12),"Ok","Não") -> Ok | AV21: =MONTH(AW21) -> 4 | AW21: =AW20+1 -> 45401 | AX21: =IF(AND(AW21>=$C$4,AW21<=$C$5),"Ok","Não") -> Ok
AH22: =MONTH(AI22) -> 11 | AI22: =AI21+1 -> 45616 | AJ22: =IF(AND(AI22>=$C$6,AI22<=$C$8),"Ok","Não") -> Ok | AL22: =MONTH(AM22) -> 8 | AM22: =AM21+1 -> 45896 | AN22: =IF(AND(AM22>=$C$9,AM22<=$C$10),"Ok","Não") -> Ok | AR22: =MONTH(AS22) -> 3 | AS22: =AS21+1 -> 46106 | AT22: =IF(AND(AS22>=$C$11,AS22<=$C$12),"Ok","Não") -> Ok | AV22: =MONTH(AW22) -> 4 | AW22: =AW21+1 -> 45402 | AX22: =IF(AND(AW22>=$C$4,AW22<=$C$5),"Ok","Não") -> Ok
AH23: =MONTH(AI23) -> 11 | AI23: =AI22+1 -> 45617 | AJ23: =IF(AND(AI23>=$C$6,AI23<=$C$8),"Ok","Não") -> Ok | AL23: =MONTH(AM23) -> 8 | AM23: =AM22+1 -> 45897 | AN23: =IF(AND(AM23>=$C$9,AM23<=$C$10),"Ok","Não") -> Ok | AR23: =MONTH(AS23) -> 3 | AS23: =AS22+1 -> 46107 | AT23: =IF(AND(AS23>=$C$11,AS23<=$C$12),"Ok","Não") -> Ok | AV23: =MONTH(AW23) -> 4 | AW23: =AW22+1 -> 45403 | AX23: =IF(AND(AW23>=$C$4,AW23<=$C$5),"Ok","Não") -> Ok
AH24: =MONTH(AI24) -> 11 | AI24: =AI23+1 -> 45618 | AJ24: =IF(AND(AI24>=$C$6,AI24<=$C$8),"Ok","Não") -> Ok | AL24: =MONTH(AM24) -> 8 | AM24: =AM23+1 -> 45898 | AN24: =IF(AND(AM24>=$C$9,AM24<=$C$10),"Ok","Não") -> Ok | AR24: =MONTH(AS24) -> 3 | AS24: =AS23+1 -> 46108 | AT24: =IF(AND(AS24>=$C$11,AS24<=$C$12),"Ok","Não") -> Ok | AV24: =MONTH(AW24) -> 4 | AW24: =AW23+1 -> 45404 | AX24: =IF(AND(AW24>=$C$4,AW24<=$C$5),"Ok","Não") -> Ok
AH25: =MONTH(AI25) -> 11 | AI25: =AI24+1 -> 45619 | AJ25: =IF(AND(AI25>=$C$6,AI25<=$C$8),"Ok","Não") -> Ok | AL25: =MONTH(AM25) -> 8 | AM25: =AM24+1 -> 45899 | AN25: =IF(AND(AM25>=$C$9,AM25<=$C$10),"Ok","Não") -> Ok | AR25: =MONTH(AS25) -> 3 | AS25: =AS24+1 -> 46109 | AT25: =IF(AND(AS25>=$C$11,AS25<=$C$12),"Ok","Não") -> Ok | AV25: =MONTH(AW25) -> 4 | AW25: =AW24+1 -> 45405 | AX25: =IF(AND(AW25>=$C$4,AW25<=$C$5),"Ok","Não") -> Ok
AH26: =MONTH(AI26) -> 11 | AI26: =AI25+1 -> 45620 | AJ26: =IF(AND(AI26>=$C$6,AI26<=$C$8),"Ok","Não") -> Ok | AL26: =MONTH(AM26) -> 8 | AM26: =AM25+1 -> 45900 | AN26: =IF(AND(AM26>=$C$9,AM26<=$C$10),"Ok","Não") -> Ok | AR26: =MONTH(AS26) -> 3 | AS26: =AS25+1 -> 46110 | AT26: =IF(AND(AS26>=$C$11,AS26<=$C$12),"Ok","Não") -> Ok | AV26: =MONTH(AW26) -> 4 | AW26: =AW25+1 -> 45406 | AX26: =IF(AND(AW26>=$C$4,AW26<=$C$5),"Ok","Não") -> Ok
AH27: =MONTH(AI27) -> 11 | AI27: =AI26+1 -> 45621 | AJ27: =IF(AND(AI27>=$C$6,AI27<=$C$8),"Ok","Não") -> Ok | AL27: =MONTH(AM27) -> 9 | AM27: =AM26+1 -> 45901 | AN27: =IF(AND(AM27>=$C$9,AM27<=$C$10),"Ok","Não") -> Ok | AR27: =MONTH(AS27) -> 3 | AS27: =AS26+1 -> 46111 | AT27: =IF(AND(AS27>=$C$11,AS27<=$C$12),"Ok","Não") -> Ok | AV27: =MONTH(AW27) -> 4 | AW27: =AW26+1 -> 45407 | AX27: =IF(AND(AW27>=$C$4,AW27<=$C$5),"Ok","Não") -> Ok
AH28: =MONTH(AI28) -> 11 | AI28: =AI27+1 -> 45622 | AJ28: =IF(AND(AI28>=$C$6,AI28<=$C$8),"Ok","Não") -> Ok | AL28: =MONTH(AM28) -> 9 | AM28: =AM27+1 -> 45902 | AN28: =IF(AND(AM28>=$C$9,AM28<=$C$10),"Ok","Não") -> Ok | AR28: =MONTH(AS28) -> 3 | AS28: =AS27+1 -> 46112 | AT28: =IF(AND(AS28>=$C$11,AS28<=$C$12),"Ok","Não") -> Ok | AV28: =MONTH(AW28) -> 4 | AW28: =AW27+1 -> 45408 | AX28: =IF(AND(AW28>=$C$4,AW28<=$C$5),"Ok","Não") -> Ok
AH29: =MONTH(AI29) -> 11 | AI29: =AI28+1 -> 45623 | AJ29: =IF(AND(AI29>=$C$6,AI29<=$C$8),"Ok","Não") -> Ok | AL29: =MONTH(AM29) -> 9 | AM29: =AM28+1 -> 45903 | AN29: =IF(AND(AM29>=$C$9,AM29<=$C$10),"Ok","Não") -> Ok | AR29: =MONTH(AS29) -> 4 | AS29: =AS28+1 -> 46113 | AT29: =IF(AND(AS29>=$C$11,AS29<=$C$12),"Ok","Não") -> Ok | AV29: =MONTH(AW29) -> 4 | AW29: =AW28+1 -> 45409 | AX29: =IF(AND(AW29>=$C$4,AW29<=$C$5),"Ok","Não") -> Ok
AH30: =MONTH(AI30) -> 11 | AI30: =AI29+1 -> 45624 | AJ30: =IF(AND(AI30>=$C$6,AI30<=$C$8),"Ok","Não") -> Ok | AL30: =MONTH(AM30) -> 9 | AM30: =AM29+1 -> 45904 | AN30: =IF(AND(AM30>=$C$9,AM30<=$C$10),"Ok","Não") -> Ok | AR30: =MONTH(AS30) -> 4 | AS30: =AS29+1 -> 46114 | AT30: =IF(AND(AS30>=$C$11,AS30<=$C$12),"Ok","Não") -> Ok | AV30: =MONTH(AW30) -> 4 | AW30: =AW29+1 -> 45410 | AX30: =IF(AND(AW30>=$C$4,AW30<=$C$5),"Ok","Não") -> Ok
AH31: =MONTH(AI31) -> 11 | AI31: =AI30+1 -> 45625 | AJ31: =IF(AND(AI31>=$C$6,AI31<=$C$8),"Ok","Não") -> Ok | AL31: =MONTH(AM31) -> 9 | AM31: =AM30+1 -> 45905 | AN31: =IF(AND(AM31>=$C$9,AM31<=$C$10),"Ok","Não") -> Ok | AR31: =MONTH(AS31) -> 4 | AS31: =AS30+1 -> 46115 | AT31: =IF(AND(AS31>=$C$11,AS31<=$C$12),"Ok","Não") -> Ok | AV31: =MONTH(AW31) -> 4 | AW31: =AW30+1 -> 45411 | AX31: =IF(AND(AW31>=$C$4,AW31<=$C$5),"Ok","Não") -> Ok
... AH584: =MONTH(AI584) -> 6 | AI584: =AI583+1 -> 46178 | AJ584: =IF(AND(AI584>=$C$6,AI584<=$C$8),"Ok","Não") -> Não | AL584: =MONTH(AM584) -> 3 | AM584: =AM583+1 -> 46458 | AN584: =IF(AND(AM584>=$C$9,AM584<=$C$10),"Ok","Não") -> Não | AR584: =MONTH(AS584) -> 10 | AS584: =AS583+1 -> 46668 | AT584: =IF(AND(AS584>=$C$11,AS584<=$C$12),"Ok","Não") -> Não | AV584: =MONTH(AW584) -> 11 | AW584: =AW583+1 -> 45964 | AX584: =IF(AND(AW584>=$C$4,AW584<=$C$5),"Ok","Não") -> Não

Sheet Indicadores
B2: Informações
B3: N° de vacas para entrar na estação | C3: 1300
B4: Prenhas no final da estação | C4: 1100
B5: Bezerros(as) desmamados(as) | C5: 1000
B6: Peso médio de desmama | C6: 200
B7: Área útil (ha) | C7: 500
B9: Resultados
B10: Taxa de prenhez | C10: =C4/C3 -> 0.84615385
B11: Taxa de desmame | C11: =C5/C3 -> 0.76923077
B12: Kg de bezerro desmamado/vaca | C12: =(C6*C5)/C3 -> 153.84615
B13: Kg de bezerro desmamado/hectare | C13: =(C6*C5)/C7 -> 400
B14: Bezerros desmamados/hectare | C14: =C5/C7 -> 2

Sheet IATF x Touro
B1: TOURO x IATF
C4: TOURO | H4: IATF
C6: Informações | H6: Informações
C7: Preço compra do touro | D7: 13000 | H7: R$/protocolo | I7: 70
C8: Vida útil (anos) | D8: 5 | H8: % prenhez do protocolo | I8: 0.5
C9: Bezerros por ano | D9: 25
C10: R$/cab/mês | D10: 50 | H10: Resultados
C11: Exames anuais | D11: 300 | H11: Custo/prenhez | I11: =I7/I8 -> 140
C12: % inviabilidade | D12: 0.3
C13: R$ de "revenda" | D13: 4000
C15: Resultados
C16: Custo anual do touro | D16: =((12*D10)+D11)*(1+D12) -> 1170
C17: Custo total do touro | D17: =D7+(D16*D8) -> 18850
C18: Custo - revenda | D18: =D17-D13 -> 14850
C19: Custo/prenhez | D19: =D18/(D9*D8) -> 118.8
C23: Simulação de custos Touro | H23: Simulação de custos IATF
C24: Qnt. De vacas | D24: 125 | H24: Qnt. De vacas | I24: 500
C25: Relação touro x vaca | D25: 25 | H25: R$/protocolo | I25: 70
C26: n° de touros necessários | D26: =D24/D25 -> 5 | H26: % prenhez 1° IATF | I26: 0.5
C27: Prenhez | D27: 0.4 | H27: % prenhez 2° IATF | I27: 0.5
C28: n° de prenhas | D28: =D27*D24 -> 50 | H28: n° de prenhas | I28: =ROUND((I24*I26)+(I24-(I24*I26))*I27,0) -> 375
C29: R$ compra de touros | D29: =D26*D7 -> 65000 | H29: R$ com protocolos | I29: =(I24+(I24*(1-I26)))*I25 -> 52500
C30: R$ anual touros | D30: =D26*D16+((D29-(D13*D26))/D8) -> 14850 | H30: R$/prenhez | I30: =I29/I28 -> 140
C31: R$/prenhez | D31: =D30/(D28) -> 297

Sheet 1 IATF + Touro
B1: PROGRAMAÇÃO DA ESTAÇÃO REPRODUTIVA
B3: Mês | C3: J | D3: A | E3: S | F3: O | G3: N | H3: D | I3: J | J3: F | K3: M | L3: A | M3: M | N3: J | O3: J | P3: A | Q3: S | R3: O | S3: N | T3: D | U3: J | V3: F | W3: M | X3: A | Y3: M | Z3: J
B4: Nascimentos | D4: 100 | E4: 80 | F4: 50 | G4: 30
B5: 1° mandada | E5: =IF(C4="","",C4) | F5: =IF(D4="","",D4) -> 100 | G5: =IF(E4="","",E4) -> 80 | H5: =IF(F4="","",F4) -> 50 | I5: =IF(G4="","",G4) -> 30 | J5: =IF(H4="","",H4) | K5: =IF(I4="","",I4) | L5: =IF(J4="","",J4) | ... Z5: =IF(X4="","",X4)
B6: Prenhez 1° IATF | F6: 0.5 | G6: 0.5 | H6: 0.5 | I6: 0.5
B7: Touro | E7: =IF(D5="","",ROUND(D5*(1-D6),0)) | F7: =IF(E5="","",ROUND(E5*(1-E6),0)) | G7: =IF(F5="","",ROUND(F5*(1-F6),0)) -> 50 | H7: =IF(G5="","",ROUND(G5*(1-G6),0)) -> 40 | I7: =IF(H5="","",ROUND(H5*(1-H6),0)) -> 25 | J7: =IF(I5="","",ROUND(I5*(1-I6),0)) -> 15 | K7: =IF(J5="","",ROUND(J5*(1-J6),0)) | L7: =IF(K5="","",ROUND(K5*(1-K6),0)) | ... Z7: =IF(Y5="","",ROUND(Y5*(1-Y6),0))
B8: Prenhez touro | G8: 0.7 | H8: 0.7 | I8: 0.7 | J8: 0.7
B9: 1° Nascimentos | J9: =IF(A5="","",ROUND(A5*A6,0)) | L9: =IF(C5="","",ROUND(C5*C6,0)) | M9: =IF(D5="","",ROUND(D5*D6,0)) | N9: =IF(E5="","",ROUND(E5*E6,0)) | O9: =IF(F5="","",ROUND(F5*F6,0)) -> 50 | P9: =IF(G5="","",ROUND(G5*G6,0)) -> 40 | Q9: =IF(H5="","",ROUND(H5*H6,0)) -> 25 | R9: =IF(I5="","",ROUND(I5*I6,0)) -> 15 | S9: =IF(J5="","",ROUND(J5*J6,0)) | ... Z9: =IF(Q5="","",ROUND(Q5*Q6,0))
B10: Nascimentos Touro | L10: =IF(C7="","",ROUND(C7*C8,0)) | M10: =IF(D7="","",ROUND(D7*D8,0)) | N10: =IF(E7="","",ROUND(E7*E8,0)) | O10: =IF(F7="","",ROUND(F7*F8,0)) | P10: =IF(G7="","",ROUND(G7*G8,0)) -> 35 | Q10: =IF(H7="","",ROUND(H7*H8,0)) -> 28 | R10: =IF(I7="","",ROUND(I7*I8,0)) -> 18 | S10: =IF(J7="","",ROUND(J7*J8,0)) -> 11 | ... Z10: =IF(Q7="","",ROUND(Q7*Q8,0))
B12: Total de bezerros de IATF | D12: =SUM(C9:Z9) -> 130
B13: Total de bezerros de Touro | D13: =SUM(C10:Z10) -> 92
B14: Vacas expostas | D14: =SUM(C4:Z4) -> 260
B15: % prenhez | D15: =(D12+D13)/D14 -> 0.85384615
B16: Inseminações | D16: =SUM(C5:Z5) -> 260

Sheet 2 IATF + Touro
B1: PROGRAMAÇÃO DA ESTAÇÃO REPRODUTIVA
B3: Mês | C3: J | D3: A | E3: S | F3: O | G3: N | H3: D | I3: J | J3: F | K3: M | L3: A | M3: M | N3: J | O3: J | P3: A | Q3: S | R3: O | S3: N | T3: D | U3: J | V3: F | W3: M | X3: A | Y3: M | Z3: J
B4: Nascimentos | D4: 100 | E4: 80 | F4: 50 | G4: 30
B5: 1° mandada | E5: =IF(C4="","",C4) | F5: =IF(D4="","",D4) -> 100 | G5: =IF(E4="","",E4) -> 80 | H5: =IF(F4="","",F4) -> 50 | I5: =IF(G4="","",G4) -> 30 | J5: =IF(H4="","",H4) | K5: =IF(I4="","",I4) | L5: =IF(J4="","",J4) | ... N5: =IF(L4="","",L4) | O5: =IF(L4="","",L4) | P5: =IF(M4="","",M4) | Q5: =IF(N4="","",N4) | R5: =IF(O4="","",O4) | S5: =IF(P4="","",P4) | T5: =IF(Q4="","",Q4) | U5: =IF(R4="","",R4) | V5: =IF(S4="","",S4) | ... Z5: =IF(W4="","",W4)
B6: Prenhez | F6: 0.5 | G6: 0.5 | H6: 0.5 | I6: 0.5
B7: 2° mandada | G7: =IF(F5="","",ROUND(F5*(1-F6),0)) -> 50 | H7: =IF(G5="","",ROUND(G5*(1-G6),0)) -> 40 | I7: =IF(H5="","",ROUND(H5*(1-H6),0)) -> 25 | J7: =IF(I5="","",ROUND(I5*(1-I6),0)) -> 15 | K7: =IF(J5="","",ROUND(J5*(1-J6),0)) | L7: =IF(K5="","",ROUND(K5*(1-K6),0)) | M7: =IF(L5="","",ROUND(L5*(1-L6),0)) | N7: =IF(M5="","",ROUND(M5*(1-M6),0)) | ... Z7: =IF(Y5="","",ROUND(Y5*(1-Y6),0))
B8: Prenhez | G8: 0.5 | H8: 0.5 | I8: 0.5 | J8: 0.5
B9: Touro | H9: =IF(G7="","",ROUND((G8*G7),0)) -> 25 | I9: =IF(H7="","",ROUND((H8*H7),0)) -> 20 | J9: =IF(I7="","",ROUND((I8*I7),0)) -> 13 | K9: =IF(J7="","",ROUND((J8*J7),0)) -> 8 | L9: =IF(K7="","",ROUND((K8*K7),0)) | M9: =IF(L7="","",ROUND((L8*L7),0)) | N9: =IF(M7="","",ROUND((M8*M7),0)) | O9: =IF(N7="","",ROUND((N8*N7),0)) | ... Z9: =IF(Y7="","",ROUND((Y8*Y7),0))
B10: Prenhez | H10: 0.3 | I10: 0.3 | J10: 0.3 | K10: 0.3
B11: 1° Nascimentos | J11: =IF(A5="","",ROUND(A5*A6,0)) | L11: =IF(C5="","",ROUND(C5*C6,0)) | M11: =IF(D5="","",ROUND(D5*D6,0)) | N11: =IF(E5="","",ROUND(E5*E6,0)) | O11: =IF(F5="","",ROUND(F5*F6,0)) -> 50 | P11: =IF(G5="","",ROUND(G5*G6,0)) -> 40 | Q11: =IF(H5="","",ROUND(H5*H6,0)) -> 25 | R11: =IF(I5="","",ROUND(I5*I6,0)) -> 15 | S11: =IF(J5="","",ROUND(J5*J6,0)) | ... Z11: =IF(Q5="","",ROUND(Q5*Q6,0))
B12: 2° Nascimentos | L12: =IF(C7="","",ROUND(C7*C8,0)) | M12: =IF(D7="","",ROUND(D7*D8,0)) | N12: =IF(E7="","",ROUND(E7*E8,0)) | O12: =IF(F7="","",ROUND(F7*F8,0)) | P12: =IF(G7="","",ROUND(G7*G8,0)) -> 25 | Q12: =IF(H7="","",ROUND(H7*H8,0)) -> 20 | R12: =IF(I7="","",ROUND(I7*I8,0)) -> 13 | S12: =IF(J7="","",ROUND(J7*J8,0)) -> 8 | ... Z12: =IF(Q7="","",ROUND(Q7*Q8,0))
B13: Nascimentos Touro | K13: =IF(C10="","",ROUND(C10*C9,0)) | L13: =IF(D10="","",ROUND(D10*D9,0)) | M13: =IF(E10="","",ROUND(E10*E9,0)) | N13: =IF(F10="","",ROUND(F10*F9,0)) | O13: =IF(G10="","",ROUND(G10*G9,0)) | P13: =IF(H10="","",ROUND(H10*H9,0)) -> 8 | Q13: =IF(I10="","",ROUND(I10*I9,0)) -> 6 | R13: =IF(J10="","",ROUND(J10*J9,0)) -> 4 | ... Z13: =IF(R10="","",ROUND(R10*R9,0))
B15: Total de bezerros de IATF | D15: =SUM(C11:Z12) -> 196
B16: Total de bezerros de Touro | D16: =SUM(C13:Z13) -> 20
B17: Vacas expostas | D17: =SUM(C4:Z4) -> 260
B18: % prenhez | D18: =(D15+D16)/D17 -> 0.83076923
B19: Inseminações | D19: =SUM(C5:Z5)+SUM(C7:Z7) -> 390

Sheet Reprodutivo LANÇAR
A1: CABEÇALHO DE RESUMO DO REPRODUTIVO
A2: n° vacas expostas | B2: n° vacas 1° IATF | C2: Prenhez 1° IATF | D2: n° vacas 2° IATF | E2: Prenhez 2° IATF | F2: n° vacas c/ Touro | G2: DG final | H2: Qnt. prenha DG final | I2: DG TOTAL | J2: Qnt. paridas | K2: % nascimento | L2: Qnt. Bez desmamados | M2: % desmame | N2: Kg desm. total | O2: Kg desm./vaca exp. | P2: Kg desmamado/ha | R2: Área de pasto em hectares:
A3: =IFERROR(COUNTA(Tabela2[Coluna1]),"") -> 0 | B3: =IFERROR(COUNTIFS(Tabela2[Coluna3],">0",Tabela2[Coluna1],">0"),"") -> 0 | C3: =IFERROR(COUNTIFS(Tabela2[Coluna5],"Cheia")/COUNTA(Tabela2[Coluna5]),"") | D3: =IFERROR(COUNTIFS(Tabela2[Coluna6],">0",Tabela2[Coluna1],">0"),"") -> 0 | E3: =IFERROR(COUNTIFS(Tabela2[Coluna8],"Cheia")/COUNTA(Tabela2[Coluna8]),"") | F3: =IFERROR(COUNTIFS(Tabela2[Coluna9],">0",Tabela2[Coluna1],">0"),"") -> 0 | G3: =IFERROR(COUNTIFS(Tabela2[Coluna11],"Cheia")/COUNTIFS(Tabela2[Coluna10],">0"),"") | H3: =COUNTIFS(Tabela2[Coluna11],"Cheia") -> 0 | I3: =IFERROR(COUNTIFS(Tabela2[Coluna 16],">0")/COUNTIFS(Tabela2[Coluna1],">0"),"") | J3: =COUNTIFS(Tabela2[Coluna12],">0") -> 0 | K3: =IFERROR(J3/H3,"") | L3: =COUNTIFS(Tabela2[Coluna14],">0") -> 0 | M3: =IFERROR(L3/A3,"") | N3: =SUM(Tabela2[Coluna15]) -> 0 | O3: =IFERROR(N3/A3,"") | P3: =IFERROR(N3/S2,"")
A5: CONTROLE DE MANEJOS REPRODUTIVOS
A6: N° vaca | B6: Categoria | C6: 1° IATF | D6: 1° DG | F6: 2° IATF | G6: 2° DG | I6: Touro | J6: DG final | L6: Nasc. | N6: Desmama. | P6: Previsão de parto
C7: Data | D7: Data | E7: Resultado | F7: Data | G7: Data | H7: Resultado | I7: Data | J7: Data | K7: Resultado | L7: Data | M7: Sexo | N7: Data | O7: Peso
A8: Coluna1 | B8: Coluna2 | C8: Coluna3 | D8: Coluna4 | E8: Coluna5 | F8: Coluna6 | G8: Coluna7 | H8: Coluna8 | I8: Coluna9 | J8: Coluna10 | K8: Coluna11 | L8: Coluna12 | M8: Coluna13 | N8: Coluna14 | O8: Coluna15 | P8: Coluna 16
P9: =IF(Tabela2[[#This Row],[Coluna11]]="Vazia","Vazia",IF(Tabela2[[#This Row],[Coluna1]]="","",IF(Tabela2[[#This Row],[Coluna5]]="Cheia",Tabela2[[#This Row],[Coluna3]]+280,IF(Tabela2[[#This Row],[Coluna8]]="Cheia",Tabela2[[#This Row],[Coluna7]]+280,IF(Tabela2[[#This Row],[Coluna11]]="Cheia",Tabela2[[#This Row],[Coluna9]]+280,"Vazia")))))
P10: =IF(Tabela2[[#This Row],[Coluna11]]="Vazia","Vazia",IF(Tabela2[[#This Row],[Coluna1]]="","",IF(Tabela2[[#This Row],[Coluna5]]="Cheia",Tabela2[[#This Row],[Coluna3]]+280,IF(Tabela2[[#This Row],[Coluna8]]="Cheia",Tabela2[[#This Row],[Coluna7]]+280,IF(Tabela2[[#This Row],[Coluna11]]="Cheia",Tabela2[[#This Row],[Coluna9]]+280,"Vazia")))))
P11: =IF(Tabela2[[#This Row],[Coluna11]]="Vazia","Vazia",IF(Tabela2[[#This Row],[Coluna1]]="","",IF(Tabela2[[#This Row],[Coluna5]]="Cheia",Tabela2[[#This Row],[Coluna3]]+280,IF(Tabela2[[#This Row],[Coluna8]]="Cheia",Tabela2[[#This Row],[Coluna7]]+280,IF(Tabela2[[#This Row],[Coluna11]]="Cheia",Tabela2[[#This Row],[Coluna9]]+280,"Vazia")))))
P12: =IF(Tabela2[[#This Row],[Coluna11]]="Vazia","Vazia",IF(Tabela2[[#This Row],[Coluna1]]="","",IF(Tabela2[[#This Row],[Coluna5]]="Cheia",Tabela2[[#This Row],[Coluna3]]+280,IF(Tabela2[[#This Row],[Coluna8]]="Cheia",Tabela2[[#This Row],[Coluna7]]+280,IF(Tabela2[[#This Row],[Coluna11]]="Cheia",Tabela2[[#This Row],[Coluna9]]+280,"Vazia")))))
P13: =IF(Tabela2[[#This Row],[Coluna11]]="Vazia","Vazia",IF(Tabela2[[#This Row],[Coluna1]]="","",IF(Tabela2[[#This Row],[Coluna5]]="Cheia",Tabela2[[#This Row],[Coluna3]]+280,IF(Tabela2[[#This Row],[Coluna8]]="Cheia",Tabela2[[#This Row],[Coluna7]]+280,IF(Tabela2[[#This Row],[Coluna11]]="Cheia",Tabela2[[#This Row],[Coluna9]]+280,"Vazia")))))
P14: =IF(Tabela2[[#This Row],[Coluna11]]="Vazia","Vazia",IF(Tabela2[[#This Row],[Coluna1]]="","",IF(Tabela2[[#This Row],[Coluna5]]="Cheia",Tabela2[[#This Row],[Coluna3]]+280,IF(Tabela2[[#This Row],[Coluna8]]="Cheia",Tabela2[[#This Row],[Coluna7]]+280,IF(Tabela2[[#This Row],[Coluna11]]="Cheia",Tabela2[[#This Row],[Coluna9]]+280,"Vazia")))))
P15: =IF(Tabela2[[#This Row],[Coluna11]]="Vazia","Vazia",IF(Tabela2[[#This Row],[Coluna1]]="","",IF(Tabela2[[#This Row],[Coluna5]]="Cheia",Tabela2[[#This Row],[Coluna3]]+280,IF(Tabela2[[#This Row],[Coluna8]]="Cheia",Tabela2[[#This Row],[Coluna7]]+280,IF(Tabela2[[#This Row],[Coluna11]]="Cheia",Tabela2[[#This Row],[Coluna9]]+280,"Vazia")))))
P16: =IF(Tabela2[[#This Row],[Coluna11]]="Vazia","Vazia",IF(Tabela2[[#This Row],[Coluna1]]="","",IF(Tabela2[[#This Row],[Coluna5]]="Cheia",Tabela2[[#This Row],[Coluna3]]+280,IF(Tabela2[[#This Row],[Coluna8]]="Cheia",Tabela2[[#This Row],[Coluna7]]+280,IF(Tabela2[[#This Row],[Coluna11]]="Cheia",Tabela2[[#This Row],[Coluna9]]+280,"Vazia")))))
P17: =IF(Tabela2[[#This Row],[Coluna11]]="Vazia","Vazia",IF(Tabela2[[#This Row],[Coluna1]]="","",IF(Tabela2[[#This Row],[Coluna5]]="Cheia",Tabela2[[#This Row],[Coluna3]]+280,IF(Tabela2[[#This Row],[Coluna8]]="Cheia",Tabela2[[#This Row],[Coluna7]]+280,IF(Tabela2[[#This Row],[Coluna11]]="Cheia",Tabela2[[#This Row],[Coluna9]]+280,"Vazia")))))
P18: =IF(Tabela2[[#This Row],[Coluna11]]="Vazia","Vazia",IF(Tabela2[[#This Row],[Coluna1]]="","",IF(Tabela2[[#This Row],[Coluna5]]="Cheia",Tabela2[[#This Row],[Coluna3]]+280,IF(Tabela2[[#This Row],[Coluna8]]="Cheia",Tabela2[[#This Row],[Coluna7]]+280,IF(Tabela2[[#This Row],[Coluna11]]="Cheia",Tabela2[[#This Row],[Coluna9]]+280,"Vazia")))))
P19: =IF(Tabela2[[#This Row],[Coluna11]]="Vazia","Vazia",IF(Tabela2[[#This Row],[Coluna1]]="","",IF(Tabela2[[#This Row],[Coluna5]]="Cheia",Tabela2[[#This Row],[Coluna3]]+280,IF(Tabela2[[#This Row],[Coluna8]]="Cheia",Tabela2[[#This Row],[Coluna7]]+280,IF(Tabela2[[#This Row],[Coluna11]]="Cheia",Tabela2[[#This Row],[Coluna9]]+280,"Vazia")))))
P20: =IF(Tabela2[[#This Row],[Coluna11]]="Vazia","Vazia",IF(Tabela2[[#This Row],[Coluna1]]="","",IF(Tabela2[[#This Row],[Coluna5]]="Cheia",Tabela2[[#This Row],[Coluna3]]+280,IF(Tabela2[[#This Row],[Coluna8]]="Cheia",Tabela2[[#This Row],[Coluna7]]+280,IF(Tabela2[[#This Row],[Coluna11]]="Cheia",Tabela2[[#This Row],[Coluna9]]+280,"Vazia")))))
... P31: =IF(Tabela2[[#This Row],[Coluna11]]="Vazia","Vazia",IF(Tabela2[[#This Row],[Coluna1]]="","",IF(Tabela2[[#This Row],[Coluna5]]="Cheia",Tabela2[[#This Row],[Coluna3]]+280,IF(Tabela2[[#This Row],[Coluna8]]="Cheia",Tabela2[[#This Row],[Coluna7]]+280,IF(Tabela2[[#This Row],[Coluna11]]="Cheia",Tabela2[[#This Row],[Coluna9]]+280,"Vazia")))))

Sheet Ficha Reprodutivo IMPRIMIR
A1: CONTROLE DE MANEJOS REPRODUTIVOS
A2: N° vaca | B2: Categoria | C2: 1° IATF | D2: 1° DG | F2: 2° IATF | G2: 2° DG | I2: Touro | J2: DG final | L2: Nasc. | N2: Desmama.
C3: Data | D3: Data | E3: Resultado | F3: Data | G3: Data | H3: Resultado | I3: Data | J3: Data | K3: Resultado | L3: Data | M3: Sexo | N3: Data | O3: Peso

Sheet Formulação suplementos
C1: PLANILHA PARA FORMULAÇÃO DE SUPLEMENTOS PARA BOVINOS A PASTO
FB3: 180 | FL3: 300 | FU3: 300
FB4: Exigência | FC4: Código | FD4: Unidade | FE4: Mínimo | FF4: Ideal | FG4: Máximo | FL4: Exigência | FM4: Código | FN4: Unidade | FO4: Mínimo | FP4: Ideal | FQ4: Máximo | FU4: Exigência | FV4: Código | FW4: Unidade | FX4: Mínimo | FY4: Ideal | FZ4: Máximo
B5: INFORMAÇÕES P/ EXIGÊNCIA | E5: FORMULAÇÃO DO SUPLEMENTO | J5: EXIGÊNCIA x DIETA | R5: RESUMO DA DIETA GERAL | AH5: Ingr | AK5: Capim | FB5: Matéria Seca | FC5: MS | FD5: kg/dia | FF5: 5.5 | FG5: 6.05 | FH5: =FG5/FF5 -> 1.1 | FL5: Matéria Seca | FM5: MS | FN5: kg/dia | FP5: 6.85 | FQ5: 7.53 | FR5: =FQ5/FP5 -> 1.0992701 | FU5: Matéria Seca | FV5: MS | FW5: kg/dia | FY5: 6.85 | FZ5: 7.53 | GA5: =FZ5/FY5 -> 1.0992701
B6: Peso médio (kg) | C6: 500 | E6: Ingrediente | F6: % | G6: R$/kg | H6: R$ | J6: Descrição | K6: Ideal | L6: Máximo | M6: Dieta | N6: Resultado | O6: % na dieta | P6: % ideal | R6: Alimentos | S6: M.O. (Kg) | T6: M.S. (Kg) | U6: % P.V | V6: % da dieta | W6: Consumo total/cab | X6: Consumo total | AF6: Ureia pelo NNP | AH6: %MS | AK6: MS | AL6: NDT | AM6: PB | FB6: Extrato Etéreo | FC6: EE | FD6: kg/dia | FG6: 0.39 | FH6: =FG6/$FB$3 -> 0.0021666667 | FI6: =FG6/$FG$5 -> 0.06446281 | FL6: Extrato Etéreo | FM6: EE | FN6: kg/dia | FQ6: 0.48 | FR6: =FQ6/FL$3 -> 0.0016 | FS6: =FQ6/FQ$5 -> 0.06374502 | FU6: Extrato Etéreo | FV6: EE | FW6: kg/dia | FZ6: 0.48 | GA6: =FZ6/FU$3 -> 0.0016 | GB6: =FZ6/FZ$5 -> 0.06374502
B7: GMD (kg/cab/dia) | C7: 0.01 | H7: =G7*F7 -> 0 | J7: Matéria seca (MS) | K7: =CA33*C6/1000 -> 8.9038128 | L7: =K7*1.05 -> 9.3490035 | M7: =IFERROR(T21,0) -> 8.9038128 | N7: =IF(K7="","",IF(M7>L7,"Reduzir",IF(M7<K7,"Aumentar",IF(M7=K7,"Ok",IF(M7=L7,"Ok",IF(OR(M7>=K7,M7<=L7),"Ok")))))) -> Ok | O7: =IF(M7=0,"", $T$21/M7) -> 1 | P7: =IF(M7=0,"",K7/ $T$21) -> 1 | R7: =IF(C18="","",C18) -> Capim Mombaça | S7: =IF(IFERROR((K7-(C6*C19*AH20))/VLOOKUP(C18,'Formulação suplementos'!$B$29:$C$40,2,0),0)=0,"",IFERROR((K7-(C6*C19*AH20))/VLOOKUP(C18,'Formulação suplementos'!$B$29:$C$40,2,0),0)) -> 32.977085 | T7: =IF(R7="","",IFERROR(S7*(VLOOKUP(R7,'Formulação suplementos'!$B$29:$W$40,2,)),0)) -> 8.9038128 | U7: =IFERROR(T7/$C$6,"") -> 0.017807626 | V7: =IFERROR(T7/$T$21,"") -> 1 | W7: =IFERROR(X7/$C$20,"") -> 4946.5627 | X7: =IFERROR(S7*$C$16*$C$20,"") -> 494656.27 | AF7: =IFERROR(VLOOKUP(R7,'Formulação suplementos'!$B$56:$W$68,22,0)*T7,"") | AH7: =IF(E7="Ureia",F7,IFERROR(VLOOKUP(E7,'Formulação suplementos'!$B$43:$C$54,2,0)*F7,"")) | AK7: =VLOOKUP(R7,B29:E40,2,0) -> 0.27 | AL7: =VLOOKUP(R7,B29:E40,3,0) -> 0.59 | AM7: =VLOOKUP(R7,B29:E40,4,0) -> 0.12 | AV7: 3 | AW7: =AV7+1 -> 4 | AX7: =AW7+1 -> 5 | AY7: =AX7+1 -> 6 | AZ7: =AY7+1 -> 7 | BA7: =AZ7+1 -> 8 | BB7: =BA7+1 -> 9 | BC7: =BB7+1 -> 10 | BD7: =BC7+1 -> 11 | ... BM7: =BL7+1 -> 20 | FB7: Carboidratos Não Fibrosos | FC7: CNF | FD7: kg/dia | FG7: 4.4 | FH7: =FG7/$FB$3 -> 0.024444444 | FI7: =FG7/$FG$5 -> 0.72727273 | FL7: Carboidratos Não Fibrosos | FM7: CNF | FN7: kg/dia | FQ7: 5.48 | FR7: =FQ7/FL$3 -> 0.018266667 | FS7: =FQ7/FQ$5 -> 0.72775564 | FU7: Carboidratos Não Fibrosos | FV7: CNF | FW7: kg/dia | FZ7: 5.48 | GA7: =FZ7/FU$3 -> 0.018266667 | GB7: =FZ7/FZ$5 -> 0.72775564
B8: Categoria | C8: Primípara | H8: =G8*F8 -> 0 | J8: Extrato etéreo (EE) | K8: =IF(C6="","","Não consta") -> Não consta | L8: =IFERROR(L7*0.063,"") -> 0.58898722 | M8: =BB24/1000 -> 0.15403596 | N8: =IF(L8="","",IF(M8>L8,"Reduzir","Ok")) -> Ok | O8: =IF(M8=0,"", M8/$M$7) -> 0.0173 | P8: =IF(C6="","","Não consta") -> Não consta | R8: =IF(F7=0,"",IF(E7="","",E7)) | S8: =IF(IF(R8="","",F7*$AB$7)=0,"",IF(R8="","",F7*$AB$7)) | T8: =IF(R8="Ureia",S8,IF(S8="","",IFERROR(S8*(VLOOKUP(R8,'Formulação suplementos'!$B$42:$W$54,2,)),0))) | U8: =IFERROR(T8/$C$6,"") | V8: =IFERROR(T8/$T$21,"") | W8: =IFERROR(X8/$C$20,"") | X8: =IFERROR(S8*$C$16*$C$20,"") | AF8: =IFERROR(VLOOKUP(R8,'Formulação suplementos'!$B$56:$W$68,22,0)*T8,"") | AH8: =IF(E8="Ureia",F8,IFERROR(VLOOKUP(E8,'Formulação suplementos'!$B$43:$C$54,2,0)*F8,"")) | AV8: NDT (Kg) | AW8: P.B (Kg) | AX8: Ca (g) | AY8: P (g) | AZ8: PDR (kg) | BA8: FDN (kg) | BB8: EE (g) | BC8: Mg (g) | BD8: Na (g) | BE8: K (g) | BF8: S (g) | BG8: Cu (mg) | BH8: Zn (mg) | BI8: Fe (mg) | BJ8: Mn (mg) | BK8: I (mg) | BL8: Co (mg) | BM8: Se (mg) | FB8: Fibra em Detergente Neutro | FC8: FDN | FD8: kg/dia | FE8: 1.38 | FG8: 2.38 | FH8: =FG8/$FB$3 -> 0.013222222 | FI8: =FG8/$FG$5 -> 0.39338843 | FJ8: =FE8/FF5 -> 0.25090909 | FL8: Fibra em Detergente Neutro | FM8: FDN | FN8: kg/dia | FO8: 1.71 | FQ8: 3.96 | FR8: =FQ8/FL$3 -> 0.0132 | FS8: =FQ8/FQ$5 -> 0.52589641 | FT8: =FO8/FP5 -> 0.24963504 | FU8: Fibra em Detergente Neutro | FV8: FDN | FW8: kg/dia | FX8: 1.71 | FZ8: 3.96 | GA8: =FZ8/FU$3 -> 0.0132 | GB8: =FZ8/FZ$5 -> 0.52589641 | GC8: =FX8/FY5 -> 0.24963504
B9: Estado fisiológico | C9: Lactante | H9: =G9*F9 -> 0 | J9: FDN | K9: =IFERROR(ROUND(K7*0.25,2),"") -> 2.23 | L9: =IF(C6="","",ROUND(C6*1.32%,2)) -> 6.6 | M9: =BA24 -> 4.4519064 | N9: =IF(K9="","",IF(M9>L9,"Reduzir",IF(M9<K9,"Aumentar",IF(M9=K9,"Ok",IF(M9=L9,"Ok",IF(OR(M9>=K9,M9<=L9),"Ok")))))) -> Ok | O9: =IF(M9=0,"", M9/$M$7) -> 0.5 | P9: =IF(M9=0,"", K9/$T$21) -> 0.2504545 | R9: =IF(F8=0,"",IF(E8="","",E8)) | S9: =IF(IF(R9="","",F8*$AB$7)=0,"",IF(R9="","",F8*$AB$7)) | T9: =IF(R9="Ureia",S9,IF(S9="","",IFERROR(S9*(VLOOKUP(R9,'Formulação suplementos'!$B$42:$W$54,2,)),0))) | U9: =IFERROR(T9/$C$6,"") | V9: =IFERROR(T9/$T$21,"") | W9: =IFERROR(X9/$C$20,"") | X9: =IFERROR(S9*$C$16*$C$20,"") | AF9: =IFERROR(VLOOKUP(R9,'Formulação suplementos'!$B$56:$W$68,22,0)*T9,"") | AH9: =IF(E9="Ureia",F9,IFERROR(VLOOKUP(E9,'Formulação suplementos'!$B$43:$C$54,2,0)*F9,"")) | AK9: %EF colheita | AV9: =IFERROR($T$7*(VLOOKUP($R$7,'Formulação suplementos'!$B$29:$W$40,AV7,0)),0) -> 5.2532496 | AW9: =IFERROR($T$7*(VLOOKUP($R$7,'Formulação suplementos'!$B$29:$W$40,AW7,0)),0) -> 1.0684575 | AX9: =IFERROR($T$7*(VLOOKUP($R$7,'Formulação suplementos'!$B$29:$W$40,AX7,0)*1000),0) -> 65.888215 | AY9: =IFERROR($T$7*(VLOOKUP($R$7,'Formulação suplementos'!$B$29:$W$40,AY7,0)*1000),0) -> 16.917244 | AZ9: =IFERROR($T$7*(VLOOKUP($R$7,'Formulação suplementos'!$B$29:$W$40,AZ7,0)),0) -> 0 | BA9: =IFERROR($T$7*(VLOOKUP($R$7,'Formulação suplementos'!$B$29:$W$40,BA7,0)),0) -> 4.4519064 | BB9: =IFERROR($T$7*(VLOOKUP($R$7,'Formulação suplementos'!$B$29:$W$40,BB7,0)*1000),0) -> 154.03596 | BC9: =IFERROR($T$7*(VLOOKUP($R$7,'Formulação suplementos'!$B$29:$W$40,BC7,0)*1000),0) -> 17.807626 | BD9: =IFERROR($T$7*(VLOOKUP($R$7,'Formulação suplementos'!$B$29:$W$40,BD7,0)*1000),0) -> 0.89038128 | BE9: =IFERROR($T$7*(VLOOKUP($R$7,'Formulação suplementos'!$B$29:$W$40,BE7,0)*1000),0) -> 243.96447 | BF9: =IFERROR($T$7*(VLOOKUP($R$7,'Formulação suplementos'!$B$29:$W$40,BF7,0)*1000),0) -> 12.465338 | BG9: =IFERROR($T$7*(VLOOKUP($R$7,'Formulação suplementos'!$B$29:$W$40,BG7,0)),0) -> 89.661395 | BH9: =IFERROR($T$7*(VLOOKUP($R$7,'Formulação suplementos'!$B$29:$W$40,BH7,0)),0) -> 238.71122 | BI9: =IFERROR($T$7*(VLOOKUP($R$7,'Formulação suplementos'!$B$29:$W$40,BI7,0)),0) -> 0 | BJ9: =IFERROR($T$7*(VLOOKUP($R$7,'Formulação suplementos'!$B$29:$W$40,BJ7,0)),0) -> 890.29224 | BK9: =IFERROR($T$7*(VLOOKUP($R$7,'Formulação suplementos'!$B$29:$W$40,BK7,0)),0) -> 0 | BL9: =IFERROR($T$7*(VLOOKUP($R$7,'Formulação suplementos'!$B$29:$W$40,BL7,0)),0) -> 3.6505633 | BM9: =IFERROR($T$7*(VLOOKUP($R$7,'Formulação suplementos'!$B$29:$W$40,BM7,0)),0) -> 0 | FB9: FDN Fisicamente Efetiva | FC9: FDNfe | FD9: kg/dia | FE9: 2.45 | FG9: 6.2 | FH9: =FG9/$FB$3 -> 0.034444444 | FI9: =FG9/$FG$5 -> 1.0247934 | FL9: FDN Fisicamente Efetiva | FM9: FDNfe | FN9: kg/dia | FO9: 2.45 | FQ9: 6.2 | FR9: =FQ9/FL$3 -> 0.020666667 | FS9: =FQ9/FQ$5 -> 0.82337317 | FU9: FDN Fisicamente Efetiva | FV9: FDNfe | FW9: kg/dia | FX9: 2.45 | FZ9: 6.2 | GA9: =FZ9/FU$3 -> 0.020666667 | GB9: =FZ9/FZ$5 -> 0.82337317
B10: Semana lactação | C10: 5 | H10: =G10*F10 -> 0 | J10: NDT | K10: =IF(C9="Gestante e lactante",(CA50/4.4)*1.087,(CA50/4.4)) -> 5.3263787 | L10: =IFERROR(K10*1.05,"") -> 5.5926976 | M10: =AV24 -> 5.2532496 | N10: =IF(K10="","",IF(M10>L10,"Reduzir",IF(M10<K10,"Aumentar",IF(M10=K10,"Ok",IF(M10=L10,"Ok",IF(OR(M10>=K10,M10<=L10),"Ok")))))) -> Aumentar | O10: =IF(M10=0,"", M10/$M$7) -> 0.59 | P10: =IF(M10=0,"", K10/$T$21) -> 0.59821324 | R10: =IF(F9=0,"",IF(E9="","",E9)) | S10: =IF(IF(R10="","",F9*$AB$7)=0,"",IF(R10="","",F9*$AB$7)) | T10: =IF(R10="Ureia",S10,IF(S10="","",IFERROR(S10*(VLOOKUP(R10,'Formulação suplementos'!$B$42:$W$54,2,)),0))) | U10: =IFERROR(T10/$C$6,"") | V10: =IFERROR(T10/$T$21,"") | W10: =IFERROR(X10/$C$20,"") | X10: =IFERROR(S10*$C$16*$C$20,"") | AF10: =IFERROR(VLOOKUP(R10,'Formulação suplementos'!$B$56:$W$68,22,0)*T10,"") | AH10: =IF(E10="Ureia",F10,IFERROR(VLOOKUP(E10,'Formulação suplementos'!$B$43:$C$54,2,0)*F10,"")) | AK10: Contínuo | AL10: 0.3 | BY10: Categoria | BZ10: Primípara | FB10: Teor de Amido | FC10: AMIDO | FD10: kg/dia | FE10: 2.45 | FG10: 6.2 | FH10: =FG10/$FB$3 -> 0.034444444 | FI10: =FG10/$FG$5 -> 1.0247934 | FL10: Teor de Amido | FM10: AMIDO | FN10: kg/dia | FO10: 2.45 | FQ10: 6.2 | FR10: =FQ10/FL$3 -> 0.020666667 | FS10: =FQ10/FQ$5 -> 0.82337317 | FU10: Teor de Amido | FV10: AMIDO | FW10: kg/dia | FX10: 2.45 | FZ10: 6.2 | GA10: =FZ10/FU$3 -> 0.020666667 | GB10: =FZ10/FZ$5 -> 0.82337317
H11: =G11*F11 -> 0 | J11: Proteína Bruta (PB) | K11: =IF(C9="Gestante e lactante",(CM40+CM38)*1.2,(CM40+CM38)) -> 1024.382 | L11: =IFERROR(K11*1.3,"") -> 1331.6967 | M11: =IFERROR(AW24*1000,0) -> 1068.4575 | N11: =IF(K11="","",IF(M11>L11,"Reduzir",IF(M11<K11,"Aumentar",IF(M11=K11,"Ok",IF(M11=L11,"Ok",IF(OR(M11>=K11,M11<=L11),"Ok")))))) -> Ok | O11: =IF(M11=0,"",(M11/1000)/$T$21) -> 0.12 | P11: =IF(M11=0,"",(K11/1000)/$T$21) -> 0.11504982 | R11: =IF(F10=0,"",IF(E10="","",E10)) | S11: =IF(IF(R11="","",F10*$AB$7)=0,"",IF(R11="","",F10*$AB$7)) | T11: =IF(R11="Ureia",S11,IF(S11="","",IFERROR(S11*(VLOOKUP(R11,'Formulação suplementos'!$B$42:$W$54,2,)),0))) | U11: =IFERROR(T11/$C$6,"") | V11: =IFERROR(T11/$T$21,"") | W11: =IFERROR(X11/$C$20,"") | X11: =IFERROR(S11*$C$16*$C$20,"") | AF11: =IFERROR(VLOOKUP(R11,'Formulação suplementos'!$B$56:$W$68,22,0)*T11,"") | AH11: =IF(E11="Ureia",F11,IFERROR(VLOOKUP(E11,'Formulação suplementos'!$B$43:$C$54,2,0)*F11,"")) | AK11: Alternado | AL11: 0.5 | AV11: =IFERROR($T8*(VLOOKUP($R8,'Formulação suplementos'!$B$42:$W$54,AV$7,0)),0) -> 0 | AW11: =IFERROR($T8*(VLOOKUP($R8,'Formulação suplementos'!$B$42:$W$54,AW$7,0)),0) -> 0 | AX11: =IFERROR($T8*(VLOOKUP($R8,'Formulação suplementos'!$B$42:$W$54,AX$7,0)*1000),0) -> 0 | AY11: =IFERROR($T8*(VLOOKUP($R8,'Formulação suplementos'!$B$42:$W$54,AY$7,0)*1000),0) -> 0 | AZ11: =IFERROR($T8*(VLOOKUP($R8,'Formulação suplementos'!$B$42:$W$54,AZ$7,0)),0) -> 0 | BA11: =IFERROR($T8*(VLOOKUP($R8,'Formulação suplementos'!$B$42:$W$54,BA$7,0)),0) -> 0 | BB11: =IFERROR($T8*(VLOOKUP($R8,'Formulação suplementos'!$B$42:$W$54,BB$7,0)*1000),0) -> 0 | BC11: =IFERROR($T8*(VLOOKUP($R8,'Formulação suplementos'!$B$42:$W$54,BC$7,0)*1000),0) -> 0 | BD11: =IFERROR($T8*(VLOOKUP($R8,'Formulação suplementos'!$B$42:$W$54,BD$7,0)*1000),0) -> 0 | BE11: =IFERROR($T8*(VLOOKUP($R8,'Formulação suplementos'!$B$42:$W$54,BE$7,0)*1000),0) -> 0 | BF11: =IFERROR($T8*(VLOOKUP($R8,'Formulação suplementos'!$B$42:$W$54,BF$7,0)*1000),0) -> 0 | BG11: =IFERROR($T8*(VLOOKUP($R8,'Formulação suplementos'!$B$42:$W$54,BG$7,0)),0) -> 0 | BH11: =IFERROR($T8*(VLOOKUP($R8,'Formulação suplementos'!$B$42:$W$54,BH$7,0)),0) -> 0 | BI11: =IFERROR($T8*(VLOOKUP($R8,'Formulação suplementos'!$B$42:$W$54,BI$7,0)),0) -> 0 | BJ11: =IFERROR($T8*(VLOOKUP($R8,'Formulação suplementos'!$B$42:$W$54,BJ$7,0)),0) -> 0 | BK11: =IFERROR($T8*(VLOOKUP($R8,'Formulação suplementos'!$B$42:$W$54,BK$7,0)),0) -> 0 | BL11: =IFERROR($T8*(VLOOKUP($R8,'Formulação suplementos'!$B$42:$W$54,BL$7,0)),0) -> 0 | BM11: =IFERROR($T8*(VLOOKUP($R8,'Formulação suplementos'!$B$42:$W$54,BM$7,0)),0) -> 0 | BZ11: Multípara | FB11: Nutrientes Digestíveis Totais | FC11: NDT | FD11: kg/dia | FE11: 3.99 | FF11: 3.99 | FG11: 4.19 | FH11: =FG11/FF11 -> 1.0501253 | FL11: Nutrientes Digestíveis Totais | FM11: NDT | FN11: kg/dia | FO11: 4.23 | FP11: 4.23 | FQ11: 4.45 | FR11: =FQ11/FP11 -> 1.0520095 | FU11: Nutrientes Digestíveis Totais | FV11: NDT | FW11: kg/dia | FX11: 4.35 | FY11: 4.35 | FZ11: 4.56 | GA11: =FZ11/FY11 -> 1.0482759
H12: =G12*F12 -> 0 | J12: Cálcio (Ca) | K12: =IFERROR(IF(C9="Gestante e lactante",ROUND(CS20*1.08,1),ROUND(CS20,1)),"") -> 22.2 | L12: =IFERROR(K12*2,"") -> 44.4 | M12: =AX24 -> 65.888215 | N12: =IF(K12="","",IF(M12>L12,"Reduzir",IF(M12<K12,"Aumentar",IF(M12=K12,"Ok",IF(M12=L12,"Ok",IF(OR(M12>=K12,M12<=L12),"Ok")))))) -> Reduzir | O12: =IF(M12=0,"",(M12/1000)/$T$21) -> 0.0074 | P12: =IF(M12=0,"",(K12/1000)/$T$21) -> 0.0024933139 | R12: =IF(F11=0,"",IF(E11="","",E11)) | S12: =IF(IF(R12="","",F11*$AB$7)=0,"",IF(R12="","",F11*$AB$7)) | T12: =IF(R12="Ureia",S12,IF(S12="","",IFERROR(S12*(VLOOKUP(R12,'Formulação suplementos'!$B$42:$W$54,2,)),0))) | U12: =IFERROR(T12/$C$6,"") | V12: =IFERROR(T12/$T$21,"") | W12: =IFERROR(X12/$C$20,"") | X12: =IFERROR(S12*$C$16*$C$20,"") | AF12: =IFERROR(VLOOKUP(R12,'Formulação suplementos'!$B$56:$W$68,22,0)*T12,"") | AH12: =IF(E13="Ureia",F13,IFERROR(VLOOKUP(E13,'Formulação suplementos'!$B$43:$C$54,2,0)*F13,"")) | AK12: Rotacionado | AL12: 0.7 | AV12: =IFERROR($T9*(VLOOKUP($R9,'Formulação suplementos'!$B$42:$W$54,AV$7,0)),0) -> 0 | AW12: =IFERROR($T9*(VLOOKUP($R9,'Formulação suplementos'!$B$42:$W$54,AW$7,0)),0) -> 0 | AX12: =IFERROR($T9*(VLOOKUP($R9,'Formulação suplementos'!$B$42:$W$54,AX$7,0)*1000),0) -> 0 | AY12: =IFERROR($T9*(VLOOKUP($R9,'Formulação suplementos'!$B$42:$W$54,AY$7,0)*1000),0) -> 0 | AZ12: =IFERROR($T9*(VLOOKUP($R9,'Formulação suplementos'!$B$42:$W$54,AZ$7,0)),0) -> 0 | BA12: =IFERROR($T9*(VLOOKUP($R9,'Formulação suplementos'!$B$42:$W$54,BA$7,0)),0) -> 0 | BB12: =IFERROR($T9*(VLOOKUP($R9,'Formulação suplementos'!$B$42:$W$54,BB$7,0)*1000),0) -> 0 | BC12: =IFERROR($T9*(VLOOKUP($R9,'Formulação suplementos'!$B$42:$W$54,BC$7,0)*1000),0) -> 0 | BD12: =IFERROR($T9*(VLOOKUP($R9,'Formulação suplementos'!$B$42:$W$54,BD$7,0)*1000),0) -> 0 | BE12: =IFERROR($T9*(VLOOKUP($R9,'Formulação suplementos'!$B$42:$W$54,BE$7,0)*1000),0) -> 0 | BF12: =IFERROR($T9*(VLOOKUP($R9,'Formulação suplementos'!$B$42:$W$54,BF$7,0)*1000),0) -> 0 | BG12: =IFERROR($T9*(VLOOKUP($R9,'Formulação suplementos'!$B$42:$W$54,BG$7,0)),0) -> 0 | BH12: =IFERROR($T9*(VLOOKUP($R9,'Formulação suplementos'!$B$42:$W$54,BH$7,0)),0) -> 0 | BI12: =IFERROR($T9*(VLOOKUP($R9,'Formulação suplementos'!$B$42:$W$54,BI$7,0)),0) -> 0 | BJ12: =IFERROR($T9*(VLOOKUP($R9,'Formulação suplementos'!$B$42:$W$54,BJ$7,0)),0) -> 0 | BK12: =IFERROR($T9*(VLOOKUP($R9,'Formulação suplementos'!$B$42:$W$54,BK$7,0)),0) -> 0 | BL12: =IFERROR($T9*(VLOOKUP($R9,'Formulação suplementos'!$B$42:$W$54,BL$7,0)),0) -> 0 | BM12: =IFERROR($T9*(VLOOKUP($R9,'Formulação suplementos'!$B$42:$W$54,BM$7,0)),0) -> 0 | FB12: Proteína Bruta | FC12: PB | FD12: g/dia | FE12: 686.93 | FF12: 686.93 | FG12: 755.63 | FH12: =FG12/FF12 -> 1.1000102 | FL12: Proteína Bruta | FM12: PB | FN12: g/dia | FO12: 777.14 | FP12: 777.14 | FQ12: 854.85 | FR12: =FQ12/FP12 -> 1.0999949 | FU12: Proteína Bruta | FV12: PB | FW12: g/dia | FX12: 754.82 | FY12: 754.82 | FZ12: 830.4 | GA12: =FZ12/FY12 -> 1.1001298
H13: =G13*F13 -> 0 | J13: Fósforo (P) | K13: =IFERROR(IF(C9="Gestante e lactante",ROUND(CS22*1.08,1),ROUND(CS22,1)),"") -> 16.9 | L13: =IFERROR(K13*2,"") -> 33.8 | M13: =AY24 -> 16.917244 | N13: =IF(K13="","",IF(M13>L13,"Reduzir",IF(M13<K13,"Aumentar",IF(M13=K13,"Ok",IF(M13=L13,"Ok",IF(OR(M13>=K13,M13<=L13),"Ok")))))) -> Ok | O13: =IF(M13=0,"",(M13/1000)/$T$21) -> 0.0019 | P13: =IF(M13=0,"",(K13/1000)/$T$21) -> 0.0018980633 | R13: =IF(F13=0,"",IF(E13="","",E13)) | S13: =IF(IF(R13="","",F13*$AB$7)=0,"",IF(R13="","",F13*$AB$7)) | T13: =IF(R13="Ureia",S13,IF(S13="","",IFERROR(S13*(VLOOKUP(R13,'Formulação suplementos'!$B$42:$W$54,2,)),0))) | U13: =IFERROR(T13/$C$6,"") | V13: =IFERROR(T13/$T$21,"") | W13: =IFERROR(X13/$C$20,"") | X13: =IFERROR(S13*$C$16*$C$20,"") | AF13: =IFERROR(VLOOKUP(R13,'Formulação suplementos'!$B$56:$W$68,22,0)*T13,"") | AH13: =IFERROR(VLOOKUP(E14,'Formulação suplementos'!$B$57:$C$68,2,0)*F14,"") | AK13: Ultra-denso | AL13: 0.95 | AV13: =IFERROR($T10*(VLOOKUP($R10,'Formulação suplementos'!$B$42:$W$54,AV$7,0)),0) -> 0 | AW13: =IFERROR($T10*(VLOOKUP($R10,'Formulação suplementos'!$B$42:$W$54,AW$7,0)),0) -> 0 | AX13: =IFERROR($T10*(VLOOKUP($R10,'Formulação suplementos'!$B$42:$W$54,AX$7,0)*1000),0) -> 0 | AY13: =IFERROR($T10*(VLOOKUP($R10,'Formulação suplementos'!$B$42:$W$54,AY$7,0)*1000),0) -> 0 | AZ13: =IFERROR($T10*(VLOOKUP($R10,'Formulação suplementos'!$B$42:$W$54,AZ$7,0)),0) -> 0 | BA13: =IFERROR($T10*(VLOOKUP($R10,'Formulação suplementos'!$B$42:$W$54,BA$7,0)),0) -> 0 | BB13: =IFERROR($T10*(VLOOKUP($R10,'Formulação suplementos'!$B$42:$W$54,BB$7,0)*1000),0) -> 0 | BC13: =IFERROR($T10*(VLOOKUP($R10,'Formulação suplementos'!$B$42:$W$54,BC$7,0)*1000),0) -> 0 | BD13: =IFERROR($T10*(VLOOKUP($R10,'Formulação suplementos'!$B$42:$W$54,BD$7,0)*1000),0) -> 0 | BE13: =IFERROR($T10*(VLOOKUP($R10,'Formulação suplementos'!$B$42:$W$54,BE$7,0)*1000),0) -> 0 | BF13: =IFERROR($T10*(VLOOKUP($R10,'Formulação suplementos'!$B$42:$W$54,BF$7,0)*1000),0) -> 0 | BG13: =IFERROR($T10*(VLOOKUP($R10,'Formulação suplementos'!$B$42:$W$54,BG$7,0)),0) -> 0 | BH13: =IFERROR($T10*(VLOOKUP($R10,'Formulação suplementos'!$B$42:$W$54,BH$7,0)),0) -> 0 | BI13: =IFERROR($T10*(VLOOKUP($R10,'Formulação suplementos'!$B$42:$W$54,BI$7,0)),0) -> 0 | BJ13: =IFERROR($T10*(VLOOKUP($R10,'Formulação suplementos'!$B$42:$W$54,BJ$7,0)),0) -> 0 | BK13: =IFERROR($T10*(VLOOKUP($R10,'Formulação suplementos'!$B$42:$W$54,BK$7,0)),0) -> 0 | BL13: =IFERROR($T10*(VLOOKUP($R10,'Formulação suplementos'!$B$42:$W$54,BL$7,0)),0) -> 0 | BM13: =IFERROR($T10*(VLOOKUP($R10,'Formulação suplementos'!$B$42:$W$54,BM$7,0)),0) -> 0 | FB13: Cálcio | FC13: Ca | FD13: g/dia | FE13: 33.1 | FF13: 33.1 | FG13: 66.21 | FH13: =FG13/FF13 -> 2.0003021 | FL13: Cálcio | FM13: Ca | FN13: g/dia | FO13: 22 | FP13: 22 | FQ13: 43.99 | FR13: =FQ13/FP13 -> 1.9995455 | FU13: Cálcio | FV13: Ca | FW13: g/dia | FX13: 21.77 | FY13: 21.77 | FZ13: 43.54 | GA13: =FZ13/FY13 -> 2
H14: =G14*F14 -> 0 | J14: Magnésio (mg) | K14: =IFERROR(IF(C9="Gestante e lactante",ROUND(CS25*1.15,1),ROUND(CS25,1)),"") -> 9.5 | L14: =IFERROR(K14*3,"") -> 28.5 | M14: =BC24 -> 0 | N14: =IF(K14="","",IF(M14>L14,"Reduzir",IF(M14<K14,"Aumentar",IF(M14=K14,"Ok",IF(M14=L14,"Ok",IF(OR(M14>=K14,M14<=L14),"Ok")))))) -> Aumentar | O14: =IF(M14=0,"",(M14/1000)/$T$21) | P14: =IF(M14=0,"",(K14/1000)/$T$21) | R14: =IF(F14=0,"",IF(E14="","",E14)) | S14: =IF(IF(R14="","",F14*$AB$7)=0,"",IF(R14="","",F14*$AB$7)) | T14: =IF(S14="","",IFERROR(S14*(VLOOKUP(R14,'Formulação suplementos'!$B$56:$W$68,2,)),0)) | U14: =IFERROR(T14/$C$6,"") | V14: =IFERROR(T14/$T$21,"") | W14: =IFERROR(X14/$C$20,"") | X14: =IFERROR(S14*$C$16*$C$20,"") | AF14: =IFERROR(VLOOKUP(R14,'Formulação suplementos'!$B$56:$W$68,22,0)*T14,"") | AH14: =IFERROR(VLOOKUP(E15,'Formulação suplementos'!$B$57:$C$68,2,0)*F15,"") | AK14: Ponta 7X | AL14: 0.8 | AV14: =IFERROR($T11*(VLOOKUP($R11,'Formulação suplementos'!$B$42:$W$54,AV$7,0)),0) -> 0 | AW14: =IFERROR($T11*(VLOOKUP($R11,'Formulação suplementos'!$B$42:$W$54,AW$7,0)),0) -> 0 | AX14: =IFERROR($T11*(VLOOKUP($R11,'Formulação suplementos'!$B$42:$W$54,AX$7,0)*1000),0) -> 0 | AY14: =IFERROR($T11*(VLOOKUP($R11,'Formulação suplementos'!$B$42:$W$54,AY$7,0)*1000),0) -> 0 | AZ14: =IFERROR($T11*(VLOOKUP($R11,'Formulação suplementos'!$B$42:$W$54,AZ$7,0)),0) -> 0 | BA14: =IFERROR($T11*(VLOOKUP($R11,'Formulação suplementos'!$B$42:$W$54,BA$7,0)),0) -> 0 | BB14: =IFERROR($T11*(VLOOKUP($R11,'Formulação suplementos'!$B$42:$W$54,BB$7,0)*1000),0) -> 0 | BC14: =IFERROR($T11*(VLOOKUP($R11,'Formulação suplementos'!$B$42:$W$54,BC$7,0)*1000),0) -> 0 | BD14: =IFERROR($T11*(VLOOKUP($R11,'Formulação suplementos'!$B$42:$W$54,BD$7,0)*1000),0) -> 0 | BE14: =IFERROR($T11*(VLOOKUP($R11,'Formulação suplementos'!$B$42:$W$54,BE$7,0)*1000),0) -> 0 | BF14: =IFERROR($T11*(VLOOKUP($R11,'Formulação suplementos'!$B$42:$W$54,BF$7,0)*1000),0) -> 0 | BG14: =IFERROR($T11*(VLOOKUP($R11,'Formulação suplementos'!$B$42:$W$54,BG$7,0)),0) -> 0 | BH14: =IFERROR($T11*(VLOOKUP($R11,'Formulação suplementos'!$B$42:$W$54,BH$7,0)),0) -> 0 | BI14: =IFERROR($T11*(VLOOKUP($R11,'Formulação suplementos'!$B$42:$W$54,BI$7,0)),0) -> 0 | BJ14: =IFERROR($T11*(VLOOKUP($R11,'Formulação suplementos'!$B$42:$W$54,BJ$7,0)),0) -> 0 | BK14: =IFERROR($T11*(VLOOKUP($R11,'Formulação suplementos'!$B$42:$W$54,BK$7,0)),0) -> 0 | BL14: =IFERROR($T11*(VLOOKUP($R11,'Formulação suplementos'!$B$42:$W$54,BL$7,0)),0) -> 0 | BM14: =IFERROR($T11*(VLOOKUP($R11,'Formulação suplementos'!$B$42:$W$54,BM$7,0)),0) -> 0 | FB14: Fósforo | FC14: P | FD14: g/dia | FE14: 17.04 | FF14: 17.04 | FG14: 34.08 | FH14: =FG14/FF14 -> 2 | FL14: Fósforo | FM14: P | FN14: g/dia | FO14: 13.5 | FP14: 13.5 | FQ14: 27.01 | FR14: =FQ14/FP14 -> 2.0007407 | FU14: Fósforo | FV14: P | FW14: g/dia | FX14: 13.43 | FY14: 13.43 | FZ14: 26.85 | GA14: =FZ14/FY14 -> 1.9992554
B15: INFORMAÇÕES DO SISTEMA | H15: =G15*F15 -> 0 | J15: Potássio (K) | K15: =IFERROR(IF(C9="Gestante e lactante",ROUND(CS29*1.15,1),ROUND(CS29,1)),"") -> 33.1 | L15: =IFERROR(K15*3,"") -> 99.3 | M15: =BE24 -> 243.96447 | N15: =IF(K15="","",IF(M15>L15,"Reduzir",IF(M15<K15,"Aumentar",IF(M15=K15,"Ok",IF(M15=L15,"Ok",IF(OR(M15>=K15,M15<=L15),"Ok")))))) -> Reduzir | O15: =IF(M15=0,"",(M15/1000)/$T$21) -> 0.0274 | P15: =IF(M15=0,"",(K15/1000)/$T$21) -> 0.0037175085 | R15: =IF(F15=0,"",IF(E15="","",E15)) | S15: =IF(IF(R15="","",F15*$AB$7)=0,"",IF(R15="","",F15*$AB$7)) | T15: =IF(S15="","",IFERROR(S15*(VLOOKUP(R15,'Formulação suplementos'!$B$56:$W$68,2,)),0)) | U15: =IFERROR(T15/$C$6,"") | V15: =IFERROR(T15/$T$21,"") | W15: =IFERROR(X15/$C$20,"") | X15: =IFERROR(S15*$C$16*$C$20,"") | AF15: =IFERROR(VLOOKUP(R15,'Formulação suplementos'!$B$56:$W$68,22,0)*T15,"") | AH15: =IFERROR(VLOOKUP(E16,'Formulação suplementos'!$B$57:$C$68,2,0)*F16,"") | AV15: =IFERROR($T12*(VLOOKUP($R12,'Formulação suplementos'!$B$42:$W$54,AV$7,0)),0) -> 0 | AW15: =IFERROR($T12*(VLOOKUP($R12,'Formulação suplementos'!$B$42:$W$54,AW$7,0)),0) -> 0 | AX15: =IFERROR($T12*(VLOOKUP($R12,'Formulação suplementos'!$B$42:$W$54,AX$7,0)*1000),0) -> 0 | AY15: =IFERROR($T12*(VLOOKUP($R12,'Formulação suplementos'!$B$42:$W$54,AY$7,0)*1000),0) -> 0 | AZ15: =IFERROR($T12*(VLOOKUP($R12,'Formulação suplementos'!$B$42:$W$54,AZ$7,0)),0) -> 0 | BA15: =IFERROR($T12*(VLOOKUP($R12,'Formulação suplementos'!$B$42:$W$54,BA$7,0)),0) -> 0 | BB15: =IFERROR($T12*(VLOOKUP($R12,'Formulação suplementos'!$B$42:$W$54,BB$7,0)*1000),0) -> 0 | BC15: =IFERROR($T12*(VLOOKUP($R12,'Formulação suplementos'!$B$42:$W$54,BC$7,0)*1000),0) -> 0 | BD15: =IFERROR($T12*(VLOOKUP($R12,'Formulação suplementos'!$B$42:$W$54,BD$7,0)*1000),0) -> 0 | BE15: =IFERROR($T12*(VLOOKUP($R12,'Formulação suplementos'!$B$42:$W$54,BE$7,0)*1000),0) -> 0 | BF15: =IFERROR($T12*(VLOOKUP($R12,'Formulação suplementos'!$B$42:$W$54,BF$7,0)*1000),0) -> 0 | BG15: =IFERROR($T12*(VLOOKUP($R12,'Formulação suplementos'!$B$42:$W$54,BG$7,0)),0) -> 0 | BH15: =IFERROR($T12*(VLOOKUP($R12,'Formulação suplementos'!$B$42:$W$54,BH$7,0)),0) -> 0 | BI15: =IFERROR($T12*(VLOOKUP($R12,'Formulação suplementos'!$B$42:$W$54,BI$7,0)),0) -> 0 | BJ15: =IFERROR($T12*(VLOOKUP($R12,'Formulação suplementos'!$B$42:$W$54,BJ$7,0)),0) -> 0 | BK15: =IFERROR($T12*(VLOOKUP($R12,'Formulação suplementos'!$B$42:$W$54,BK$7,0)),0) -> 0 | BL15: =IFERROR($T12*(VLOOKUP($R12,'Formulação suplementos'!$B$42:$W$54,BL$7,0)),0) -> 0 | BM15: =IFERROR($T12*(VLOOKUP($R12,'Formulação suplementos'!$B$42:$W$54,BM$7,0)),0) -> 0 | DN15: Sem Lac | DO15: 2 | DS15: GMD | DT15: 0.2 | FB15: Magnésio | FC15: Mg | FD15: g/dia | FE15: 4.13 | FF15: 4.13 | FG15: 12.38 | FH15: =FG15/FF15 -> 2.9975787 | FL15: Magnésio | FM15: Mg | FN15: g/dia | FO15: 5.99 | FP15: 5.99 | FQ15: 17.96 | FR15: =FQ15/FP15 -> 2.9983306 | FU15: Magnésio | FV15: Mg | FW15: g/dia | FX15: 5.99 | FY15: 5.99 | FZ15: 17.96 | GA15: =FZ15/FY15 -> 2.9983306
B16: Dias de uso | C16: 150 | H16: =G16*F16 -> 0 | J16: Sódio (Na) | K16: =IFERROR(IF(C9="Gestante e lactante",ROUND(CS27*1.15,1),ROUND(CS27,1)),"") -> 11.8 | L16: =IFERROR(K16*6,"") -> 70.8 | M16: =BD24 -> 0.89038128 | N16: =IF(K16="","",IF(M16>L16,"Reduzir",IF(M16<K16,"Aumentar",IF(M16=K16,"Ok",IF(M16=L16,"Ok",IF(OR(M16>=K16,M16<=L16),"Ok")))))) -> Aumentar | O16: =IF(M16=0,"",(M16/1000)/$T$21) -> 0.0001 | P16: =IF(M16=0,"",(K16/1000)/$T$21) -> 0.0013252749 | R16: =IF(F16=0,"",IF(E16="","",E16)) | S16: =IF(IF(R16="","",F16*$AB$7)=0,"",IF(R16="","",F16*$AB$7)) | T16: =IF(S16="","",IFERROR(S16*(VLOOKUP(R16,'Formulação suplementos'!$B$56:$W$68,2,)),0)) | U16: =IFERROR(T16/$C$6,"") | V16: =IFERROR(T16/$T$21,"") | W16: =IFERROR(X16/$C$20,"") | X16: =IFERROR(S16*$C$16*$C$20,"") | AF16: =IFERROR(VLOOKUP(R16,'Formulação suplementos'!$B$56:$W$68,22,0)*T16,"") | AH16: =IFERROR(VLOOKUP(E17,'Formulação suplementos'!$B$57:$C$68,2,0)*F17,"") | AV16: =IFERROR($T13*(VLOOKUP($R13,'Formulação suplementos'!$B$42:$W$54,AV$7,0)),0) -> 0 | AW16: =IFERROR($T13*(VLOOKUP($R13,'Formulação suplementos'!$B$42:$W$54,AW$7,0)),0) -> 0 | AX16: =IFERROR($T13*(VLOOKUP($R13,'Formulação suplementos'!$B$42:$W$54,AX$7,0)*1000),0) -> 0 | AY16: =IFERROR($T13*(VLOOKUP($R13,'Formulação suplementos'!$B$42:$W$54,AY$7,0)*1000),0) -> 0 | AZ16: =IFERROR($T13*(VLOOKUP($R13,'Formulação suplementos'!$B$42:$W$54,AZ$7,0)),0) -> 0 | BA16: =IFERROR($T13*(VLOOKUP($R13,'Formulação suplementos'!$B$42:$W$54,BA$7,0)),0) -> 0 | BB16: =IFERROR($T13*(VLOOKUP($R13,'Formulação suplementos'!$B$42:$W$54,BB$7,0)*1000),0) -> 0 | BC16: =IFERROR($T13*(VLOOKUP($R13,'Formulação suplementos'!$B$42:$W$54,BC$7,0)*1000),0) -> 0 | BD16: =IFERROR($T13*(VLOOKUP($R13,'Formulação suplementos'!$B$42:$W$54,BD$7,0)*1000),0) -> 0 | BE16: =IFERROR($T13*(VLOOKUP($R13,'Formulação suplementos'!$B$42:$W$54,BE$7,0)*1000),0) -> 0 | BF16: =IFERROR($T13*(VLOOKUP($R13,'Formulação suplementos'!$B$42:$W$54,BF$7,0)*1000),0) -> 0 | BG16: =IFERROR($T13*(VLOOKUP($R13,'Formulação suplementos'!$B$42:$W$54,BG$7,0)),0) -> 0 | BH16: =IFERROR($T13*(VLOOKUP($R13,'Formulação suplementos'!$B$42:$W$54,BH$7,0)),0) -> 0 | BI16: =IFERROR($T13*(VLOOKUP($R13,'Formulação suplementos'!$B$42:$W$54,BI$7,0)),0) -> 0 | BJ16: =IFERROR($T13*(VLOOKUP($R13,'Formulação suplementos'!$B$42:$W$54,BJ$7,0)),0) -> 0 | BK16: =IFERROR($T13*(VLOOKUP($R13,'Formulação suplementos'!$B$42:$W$54,BK$7,0)),0) -> 0 | BL16: =IFERROR($T13*(VLOOKUP($R13,'Formulação suplementos'!$B$42:$W$54,BL$7,0)),0) -> 0 | BM16: =IFERROR($T13*(VLOOKUP($R13,'Formulação suplementos'!$B$42:$W$54,BM$7,0)),0) -> 0 | DN16: GMD, kg | DO16: 0.1 | DS16: si | DT16: 1 | DU16: =-53.07 + (304.89 * (DT16-'Formulação suplementos'!$CA$214)) + (90.79 *('Formulação suplementos'!$CY$30)) - (3.13 *('Formulação suplementos'!$CY$30)^2) -> 260.45164 | FB16: Potássio | FC16: K | FD16: g/dia | FE16: 13.15 | FF16: 13.15 | FG16: 39.45 | FH16: =FG16/FF16 -> 3 | FL16: Potássio | FM16: K | FN16: g/dia | FO16: 18.25 | FP16: 18.25 | FQ16: 54.74 | FR16: =FQ16/FP16 -> 2.9994521 | FU16: Potássio | FV16: K | FW16: g/dia | FX16: 18.26 | FY16: 18.26 | FZ16: 54.78 | GA16: =FZ16/FY16 -> 3
