Workbook

Sheet CHUVAS
A1: ENTENDENDO O CLIMA
A2: Analisar o clima é fundamental para entender por quanto tempo seu sistema poderá ser utilizado de forma
A3: intensiva. Como a proposta desse treinamento é para que você aproveite o máximo possível o período
A4: do verão/chuvas, essa etapa vai direcionar todo o potencial do seu projeto. Quanto menos tempo disponível
A5: para intensificar, mais vocêterá que produzir, para garantir alta produção em curto espaço de tempo.
A7: Mês | B7: C° min | C7: C° Máx | D7: mm | F7: Resultado
A8: Jan | E8: > | F8: =IF(D8="","",IF(Q8=30,"Chuva",IF(Q8=0,"Seca",IF(Q8=20,"Chuva -1",IF(Q8=10,"Transição",0))))) | G8: =IF(OR(B8="",C8=""),"",IF(S8=1,"Verão",IF(S8=0,"Inverno",IF(S8=0.5,"Transição",IF(S8=0.75,"Transição",0))))) | H8: =IF(OR(F8="",G8=""),"",IF(AND(G8="Verão",F8="Chuva"),"Ok","Cuidado")) | Q8: =IF(D8="","",IF(D8>=150,30,IF(AND(D8>=120,D8<150),20,IF(AND(D8>=60,D8<120),10,0)))) | R8: =IF(OR(B8="",C8=""),"",AVERAGE(B8:C8)) | S8: =IF(R8="","",IF(AND(R8<=19,R8>=17),0.5,IF(R8<16,0,IF(AND(R8>19,R8<20),0.75,IF(R8>19,1,0))))) | T8: =IF(S8="","", S8*Q8)
A9: Fev | E9: > | F9: =IF(D9="","",IF(Q9=30,"Chuva",IF(Q9=0,"Seca",IF(Q9=20,"Chuva -1",IF(Q9=10,"Transição",0))))) | G9: =IF(OR(B9="",C9=""),"",IF(S9=1,"Verão",IF(S9=0,"Inverno",IF(S9=0.5,"Transição",IF(S9=0.75,"Transição",0))))) | H9: =IF(OR(F9="",G9=""),"",IF(AND(G9="Verão",F9="Chuva"),"Ok","Cuidado")) | Q9: =IF(D9="","",IF(D9>=150,30,IF(AND(D9>=120,D9<150),20,IF(AND(D9>=60,D9<120),10,0)))) | R9: =IF(OR(B9="",C9=""),"",AVERAGE(B9:C9)) | S9: =IF(R9="","",IF(AND(R9<=19,R9>=17),0.5,IF(R9<16,0,IF(AND(R9>19,R9<20),0.75,IF(R9>19,1,0))))) | T9: =IF(S9="","", S9*Q9)
A10: Mar | E10: > | F10: =IF(D10="","",IF(Q10=30,"Chuva",IF(Q10=0,"Seca",IF(Q10=20,"Chuva -1",IF(Q10=10,"Transição",0))))) | G10: =IF(OR(B10="",C10=""),"",IF(S10=1,"Verão",IF(S10=0,"Inverno",IF(S10=0.5,"Transição",IF(S10=0.75,"Transição",0))))) | H10: =IF(OR(F10="",G10=""),"",IF(AND(G10="Verão",F10="Chuva"),"Ok","Cuidado")) | Q10: =IF(D10="","",IF(D10>=150,30,IF(AND(D10>=120,D10<150),20,IF(AND(D10>=60,D10<120),10,0)))) | R10: =IF(OR(B10="",C10=""),"",AVERAGE(B10:C10)) | S10: =IF(R10="","",IF(AND(R10<=19,R10>=17),0.5,IF(R10<16,0,IF(AND(R10>19,R10<20),0.75,IF(R10>19,1,0))))) | T10: =IF(S10="","", S10*Q10)
A11: Abr | E11: > | F11: =IF(D11="","",IF(Q11=30,"Chuva",IF(Q11=0,"Seca",IF(Q11=20,"Chuva -1",IF(Q11=10,"Transição",0))))) | G11: =IF(OR(B11="",C11=""),"",IF(S11=1,"Verão",IF(S11=0,"Inverno",IF(S11=0.5,"Transição",IF(S11=0.75,"Transição",0))))) | H11: =IF(OR(F11="",G11=""),"",IF(AND(G11="Verão",F11="Chuva"),"Ok","Cuidado")) | Q11: =IF(D11="","",IF(D11>=150,30,IF(AND(D11>=120,D11<150),20,IF(AND(D11>=60,D11<120),10,0)))) | R11: =IF(OR(B11="",C11=""),"",AVERAGE(B11:C11)) | S11: =IF(R11="","",IF(AND(R11<=19,R11>=17),0.5,IF(R11<16,0,IF(AND(R11>19,R11<20),0.75,IF(R11>19,1,0))))) | T11: =IF(S11="","", S11*Q11)
A12: Mai | E12: > | F12: =IF(D12="","",IF(Q12=30,"Chuva",IF(Q12=0,"Seca",IF(Q12=20,"Chuva -1",IF(Q12=10,"Transição",0))))) | G12: =IF(OR(B12="",C12=""),"",IF(S12=1,"Verão",IF(S12=0,"Inverno",IF(S12=0.5,"Transição",IF(S12=0.75,"Transição",0))))) | H12: =IF(OR(F12="",G12=""),"",IF(AND(G12="Verão",F12="Chuva"),"Ok","Cuidado")) | Q12: =IF(D12="","",IF(D12>=150,30,IF(AND(D12>=120,D12<150),20,IF(AND(D12>=60,D12<120),10,0)))) | R12: =IF(OR(B12="",C12=""),"",AVERAGE(B12:C12)) | S12: =IF(R12="","",IF(AND(R12<=19,R12>=17),0.5,IF(R12<16,0,IF(AND(R12>19,R12<20),0.75,IF(R12>19,1,0))))) | T12: =IF(S12="","", S12*Q12)
A13: Jun | E13: > | F13: =IF(D13="","",IF(Q13=30,"Chuva",IF(Q13=0,"Seca",IF(Q13=20,"Chuva -1",IF(Q13=10,"Transição",0))))) | G13: =IF(OR(B13="",C13=""),"",IF(S13=1,"Verão",IF(S13=0,"Inverno",IF(S13=0.5,"Transição",IF(S13=0.75,"Transição",0))))) | H13: =IF(OR(F13="",G13=""),"",IF(AND(G13="Verão",F13="Chuva"),"Ok","Cuidado")) | Q13: =IF(D13="","",IF(D13>=150,30,IF(AND(D13>=120,D13<150),20,IF(AND(D13>=60,D13<120),10,0)))) | R13: =IF(OR(B13="",C13=""),"",AVERAGE(B13:C13)) | S13: =IF(R13="","",IF(AND(R13<=19,R13>=17),0.5,IF(R13<16,0,IF(AND(R13>19,R13<20),0.75,IF(R13>19,1,0))))) | T13: =IF(S13="","", S13*Q13)
A14: Jul | E14: > | F14: =IF(D14="","",IF(Q14=30,"Chuva",IF(Q14=0,"Seca",IF(Q14=20,"Chuva -1",IF(Q14=10,"Transição",0))))) | G14: =IF(OR(B14="",C14=""),"",IF(S14=1,"Verão",IF(S14=0,"Inverno",IF(S14=0.5,"Transição",IF(S14=0.75,"Transição",0))))) | H14: =IF(OR(F14="",G14=""),"",IF(AND(G14="Verão",F14="Chuva"),"Ok","Cuidado")) | Q14: =IF(D14="","",IF(D14>=150,30,IF(AND(D14>=120,D14<150),20,IF(AND(D14>=60,D14<120),10,0)))) | R14: =IF(OR(B14="",C14=""),"",AVERAGE(B14:C14)) | S14: =IF(R14="","",IF(AND(R14<=19,R14>=17),0.5,IF(R14<16,0,IF(AND(R14>19,R14<20),0.75,IF(R14>19,1,0))))) | T14: =IF(S14="","", S14*Q14)
A15: Ago | E15: > | F15: =IF(D15="","",IF(Q15=30,"Chuva",IF(Q15=0,"Seca",IF(Q15=20,"Chuva -1",IF(Q15=10,"Transição",0))))) | G15: =IF(OR(B15="",C15=""),"",IF(S15=1,"Verão",IF(S15=0,"Inverno",IF(S15=0.5,"Transição",IF(S15=0.75,"Transição",0))))) | H15: =IF(OR(F15="",G15=""),"",IF(AND(G15="Verão",F15="Chuva"),"Ok","Cuidado")) | Q15: =IF(D15="","",IF(D15>=150,30,IF(AND(D15>=120,D15<150),20,IF(AND(D15>=60,D15<120),10,0)))) | R15: =IF(OR(B15="",C15=""),"",AVERAGE(B15:C15)) | S15: =IF(R15="","",IF(AND(R15<=19,R15>=17),0.5,IF(R15<16,0,IF(AND(R15>19,R15<20),0.75,IF(R15>19,1,0))))) | T15: =IF(S15="","", S15*Q15)
A16: Set | E16: > | F16: =IF(D16="","",IF(Q16=30,"Chuva",IF(Q16=0,"Seca",IF(Q16=20,"Chuva -1",IF(Q16=10,"Transição",0))))) | G16: =IF(OR(B16="",C16=""),"",IF(S16=1,"Verão",IF(S16=0,"Inverno",IF(S16=0.5,"Transição",IF(S16=0.75,"Transição",0))))) | H16: =IF(OR(F16="",G16=""),"",IF(AND(G16="Verão",F16="Chuva"),"Ok","Cuidado")) | Q16: =IF(D16="","",IF(D16>=150,30,IF(AND(D16>=120,D16<150),20,IF(AND(D16>=60,D16<120),10,0)))) | R16: =IF(OR(B16="",C16=""),"",AVERAGE(B16:C16)) | S16: =IF(R16="","",IF(AND(R16<=19,R16>=17),0.5,IF(R16<16,0,IF(AND(R16>19,R16<20),0.75,IF(R16>19,1,0))))) | T16: =IF(S16="","", S16*Q16)
A17: Out | E17: > | F17: =IF(D17="","",IF(Q17=30,"Chuva",IF(Q17=0,"Seca",IF(Q17=20,"Chuva -1",IF(Q17=10,"Transição",0))))) | G17: =IF(OR(B17="",C17=""),"",IF(S17=1,"Verão",IF(S17=0,"Inverno",IF(S17=0.5,"Transição",IF(S17=0.75,"Transição",0))))) | H17: =IF(OR(F17="",G17=""),"",IF(AND(G17="Verão",F17="Chuva"),"Ok","Cuidado")) | Q17: =IF(D17="","",IF(D17>=150,30,IF(AND(D17>=120,D17<150),20,IF(AND(D17>=60,D17<120),10,0)))) | R17: =IF(OR(B17="",C17=""),"",AVERAGE(B17:C17)) | S17: =IF(R17="","",IF(AND(R17<=19,R17>=17),0.5,IF(R17<16,0,IF(AND(R17>19,R17<20),0.75,IF(R17>19,1,0))))) | T17: =IF(S17="","", S17*Q17)
A18: Nov | E18: > | F18: =IF(D18="","",IF(Q18=30,"Chuva",IF(Q18=0,"Seca",IF(Q18=20,"Chuva -1",IF(Q18=10,"Transição",0))))) | G18: =IF(OR(B18="",C18=""),"",IF(S18=1,"Verão",IF(S18=0,"Inverno",IF(S18=0.5,"Transição",IF(S18=0.75,"Transição",0))))) | H18: =IF(OR(F18="",G18=""),"",IF(AND(G18="Verão",F18="Chuva"),"Ok","Cuidado")) | Q18: =IF(D18="","",IF(D18>=150,30,IF(AND(D18>=120,D18<150),20,IF(AND(D18>=60,D18<120),10,0)))) | R18: =IF(OR(B18="",C18=""),"",AVERAGE(B18:C18)) | S18: =IF(R18="","",IF(AND(R18<=19,R18>=17),0.5,IF(R18<16,0,IF(AND(R18>19,R18<20),0.75,IF(R18>19,1,0))))) | T18: =IF(S18="","", S18*Q18)
A19: Dez | E19: > | F19: =IF(D19="","",IF(Q19=30,"Chuva",IF(Q19=0,"Seca",IF(Q19=20,"Chuva -1",IF(Q19=10,"Transição",0))))) | G19: =IF(OR(B19="",C19=""),"",IF(S19=1,"Verão",IF(S19=0,"Inverno",IF(S19=0.5,"Transição",IF(S19=0.75,"Transição",0))))) | H19: =IF(OR(F19="",G19=""),"",IF(AND(G19="Verão",F19="Chuva"),"Ok","Cuidado")) | Q19: =IF(D19="","",IF(D19>=150,30,IF(AND(D19>=120,D19<150),20,IF(AND(D19>=60,D19<120),10,0)))) | R19: =IF(OR(B19="",C19=""),"",AVERAGE(B19:C19)) | S19: =IF(R19="","",IF(AND(R19<=19,R19>=17),0.5,IF(R19<16,0,IF(AND(R19>19,R19<20),0.75,IF(R19>19,1,0))))) | T19: =IF(S19="","", S19*Q19)
A20: Total | B20: =IFERROR(AVERAGE(B8:B19),"") | C20: =IFERROR(AVERAGE(C8:C19),"") | D20: =SUM(D8:D19) -> 0
A22: Para propriedades que possuem inverno mais rigoroso, a planilha não está considerando o período
A23: de inverno como um período disponível para acúmulo de forragem. Caso você faça sobresemeadura
A24: de plantas de inverno, seu período de uso poderá ser maior. No entanto, o foco ainda é no verão.
A39: Dias disponíveis para intensificação: | E39: ="de "&COUNTIFS(H8:H19,"Ok")*30&" a "&SUM(T8:T19)&" dias disponíveis." -> de 0 a 0 dias disponíveis.
A40: Lotação aproximada LIMITE: | E40: ="de "&COUNTIFS(H8:H19,"Ok")&" a "&ROUND(SUM(T8:T19)/30,0)&" U.A/ha na época das chuvas." -> de 0 a 0 U.A/ha na época das chuvas.

Sheet Metas
B1: PLANILHA PARA PLANEJAMENTO DE METAS
E3: AVISOS
B4: SISTEMA
B5: Qnt. Cabeças | E5: =IF(C5<=250,"Quantas cabeças quer rodar nesse sistema? (no máximo 250 por lote).","REDUZIR TAMANHO DO LOTE, SEJA POR REDUÇÃO NA ÁREA OU DIMINUINDO A META DE LOTAÇÃO!") -> Quantas cabeças quer rodar nesse sistema? (no máximo 250 por lote).
B6: Peso de entrada (kg) | E6: Quanto maior esse peso, maior vai ser a lotação média e mais vai gastar com adubação. Porém, um animal que entra leve pode não ter peso de saída adequado no final do período.
B7: Dias de capim verde | D7: =C7/30 -> 0 | E7: Essa informação foi levantada no diagnóstico. Se não se lembra, volte as aulas.
B8: Peso de saída (kg) | E8: Garanta que com esse peso seu animal tenha mercado para venda, entrada no confinamento ou qualquer outra ação para aliviar pasto.
B9: GMD (kg/dia) | C9: =IF(C8="","",IFERROR((C8-C6)/C7,"")) | E9: O GMD tem que ser suficiente para que o animal tenha peso de saída no final do periodo. Não recomendo ultrapassar demais 1 kg/dia.
B10: Data de entrada | E10: Tente aproveitar o máximo possível do período de chuva. Para isso, tenha certeza que essa data está próximo ao início da estação de capim verde. Pode iniciar no final da seca se tiver massa.
B11: Data de saída | C11: =IFERROR(((C8-C6)/C9)+C10,"") | E11: A sua região tem que ter chuva suficiente para ter capim verde (ou em transição para a seca) ainda nessa data. Caso não tenha, diminua o período ou aumente o GMD para garantir que o animal saia antes.
B12: Área disponível (ha) | E12: Quantos hectares quer disponibilizar para esse sistema? Caso não saiba, vá ajustando o tamanho da área e o tamanho do lote de acordo com a lotação.
B13: Cabeças/ha | C13: =IFERROR(C5/C12,"")
B14: Lotação entrada (U.A/ha) | C14: =IFERROR((C13*C6)/450,"") | E14: =IF(C14="","",IF(C14>4,"Cuidado, essa lotação de entrada está alta. Para que ela aconteça, o capim já deve estar alto no início do período, ou com uma boa fertilidade inicial.","Ok"))
B15: Lotação média (U.A/ha) | C15: =IFERROR(AVERAGE(C14,C16),"") | E15: =IF(C15="","",IF(C15>ROUND(C7/30.3,0),"Pelo período de chuva disponível em sua região, você não conseguirá intensificar nesse nível. Diminua a meta de produção ou aumente os dias de capim verde (se for possível). Seu limite é de "&ROUND(C7/30.3,0)&" U.A/ha",IF(C15>5,"Cuidado, essa lotação média está alta. Recomendo que seu rotacionado tenha pelo menos 8 piquetes para aproveitar melhor o capim. Você aprenderá isso na aula sobre rotacionado.","Ok")))
B16: Lotação saída (U.A/ha) | C16: =IFERROR((C13*C8)/450,"") | E16: =IF(C16="","",IF(C16>6,"Cuidado, essa lotação de saída está alta. Garanta que seus animais tenham o GMD necessário para sair até final de chuva, já que provavelmente não será possível usar esse pasto na seca","Ok"))
B18: FINANCEIRO
B19: R$/@ compra | E19: Quanto está pagando na @ dos animais que rodarão no sistema (coloque mesmo que você já tenha os animais).
B20: R$/@ venda | E20: Quanto receberá pela @ desse animal na hora da venda? Caso não saiba, use o preço de hoje. Você também pode usar esse campo para simular uma possível queda.
B21: Desembolso (R$/cab/mês) | E21: Quanto você PODE gastar por cabeça/mês durante esse período? Vá simulando até chegar no máximo possível, analisando o custo operacional e total logo abaixo.
B22: R$ compra do lote | C22: =(C6/30)*C5*C19 -> 0
B23: R$ compra por cabeça | C23: =IFERROR(C22/C5,0) -> 0
B24: Custo operacional total | C24: =(C7/30)*C5*C21 -> 0 | E24: Esse valor engloba o custo operacional, exceto compra de animais. Ele varia de acordo com o "Desembolso R$/cab/mês"
B25: Custo operacional/cab | C25: =IFERROR(C24/C5,0) -> 0 | E25: Esse valor significa quanto você gastará por cabeça para desenvolver ela nesse sistema. Esse valor varia de acordo com o "Desembolso R$/cab/mês"
B26: Custo operacional/ha | C26: =IFERROR(C24/C12,0) -> 0 | E26: Esse valor significa quanto você gastará por hectare para desenvolver ela nesse sistema. Esse valor varia de acordo com o "Desembolso R$/cab/mês".
B27: Custo total total | C27: =(C22+C24) -> 0 | E27: Esse é o valor gasto total, considerando compra de animais + operacional. Varia de acordo com o "Desembolso R$/cab/mês", e a compra de animais, que depende de: quantidade de cabeças, peso e R$/@.
B28: Custo total/cab | C28: =IFERROR(C27/C5,0) -> 0 | E28: Esse valor significa quanto custará seu animal no final do sistema (compra de animais + operacional)
B29: Custo total/ha | C29: =IFERROR(C27/C12,0) -> 0 | E29: Esse valor significa quanto você irá investir por hectare (compra de animais + operacional)
B30: Faturamento total | C30: =(C8/30)*C5*C20 -> 0 | E30: Esse é o valor que irá receber depois que vender os animais no final do sistema.
B31: Faturamento/cab | C31: =IFERROR(C30/C5,0) -> 0 | E31: Valor que irá receber por cada animal.
B32: Faturamento/ha | C32: =IFERROR(C30/C12,0) -> 0 | E32: Valor que irá receber por hectare.
B33: Margem total | C33: =C30-C27 -> 0 | E33: Esse valor sobrará no seu bolso no final do período, após a venda dos animais, caso tudo ocorra como planejado.
B34: Margem/cab | C34: =IFERROR(C33/C5,0) -> 0 | E34: Esse valor significa quanto cada cabeça deu de lucro no período.
B35: Margem/ha | C35: =IFERROR(C33/C12,0) -> 0 | E35: Esse valor significa quanto você terá de lucro por hectare. O pecuarista médio brasileiro tem em torno de R$650/ha/ano
B36: Rentabilidade a.m | C36: =IFERROR((C33/C27)/D7,0) -> 0 | E36: Essa é a rentabilidade AO MÊS do seu sistema. Sempre compare com a taxa de juros atual do Brasil. Se estiver acima da taxa de juros, é porque está sendo um bom negócio.
B38: ZOOTÉCNICO
B39: @ produzidas | C39: =((C8-C6)/30)*C5 -> 0
B40: @ produzidas/hectare | C40: =IFERROR(C39/C12,0) -> 0 | E40: A média brasileira é de 6 @/ha por ano.
B41: Custo da @ produzida | C41: =IFERROR(C24/C39,0) -> 0
B43: Ao lado você tem uma simulação de como seu rotacionado irá se comportar. Isso não é garantia de resultado, mas sim o objetivo que você precisa alcançar. | E43: Data | F43: =C10 -> 0 | G43: =IF(F43="","",IF(F43=$C$11,"",IF(F43+30>$C$11,$C$11,F43+30))) -> 30 | H43: =IF(G43="","",IF(G43=$C$11,"",IF(G43+30>$C$11,$C$11,G43+30))) -> 60 | I43: =IF(H43="","",IF(H43=$C$11,"",IF(H43+30>$C$11,$C$11,H43+30))) -> 90 | J43: =IF(I43="","",IF(I43=$C$11,"",IF(I43+30>$C$11,$C$11,I43+30))) -> 120 | K43: =IF(J43="","",IF(J43=$C$11,"",IF(J43+30>$C$11,$C$11,J43+30))) -> 150 | L43: =IF(K43="","",IF(K43=$C$11,"",IF(K43+30>$C$11,$C$11,K43+30))) -> 180 | M43: =IF(L43="","",IF(L43=$C$11,"",IF(L43+30>$C$11,$C$11,L43+30))) -> 210 | N43: =IF(M43="","",IF(M43=$C$11,"",IF(M43+30>$C$11,$C$11,M43+30))) -> 240 | ... Q43: =IF(P43="","",IF(P43=$C$11,"",IF(P43+30>$C$11,$C$11,P43+30))) -> 330
E44: Peso médio | F44: =C6 -> 0 | G44: =IFERROR(F44+((G43-F43)*$C$9),"") | H44: =IFERROR(G44+((H43-G43)*$C$9),"") | I44: =IFERROR(H44+((I43-H43)*$C$9),"") | J44: =IFERROR(I44+((J43-I43)*$C$9),"") | K44: =IFERROR(J44+((K43-J43)*$C$9),"") | L44: =IFERROR(K44+((L43-K43)*$C$9),"") | M44: =IFERROR(L44+((M43-L43)*$C$9),"") | N44: =IFERROR(M44+((N43-M43)*$C$9),"") | ... Q44: =IFERROR(P44+((Q43-P43)*$C$9),"")
...

Sheet Adubação
C1: CORREÇÃO E ADUBAÇÃO
B3: Cadastro de áreas para utilizar
B5: Identificação | C5: Área (ha) | D5: Lotação (U.A/ha) | E5: V% | F5: M% | G5: CTC (cmol/dm³) | H5: % K/CTC (K/T) | I5: Ca (cmol/dm³) | J5: Mg (cmol/dm³) | K5: P (mg/dm³) | L5: Argila (g/kg) | M5: Dias capim verde
B12: Calagem | F12: =SUM(F15:F19) -> 0 | H12: =SUM(H15:H19) -> 0
B14: V% desejado | C14: PRNT Calcário (%) | D14: N.C. (ton/ha) | E14: Calcário | F14: Total (ton) | G14: R$/ton | H14: R$ Total | I14: R$/ha | J14: Recomendação
D15: =IF(OR(B6=0,B6=""),"",IF(ROUND(IFERROR(IF(((Adubação!$B15-E6)*G6)/Adubação!$C15<0,0,((Adubação!$B15-E6)*G6)/Adubação!$C15),"S/ infos"),1)<1,0,ROUND(IFERROR(IF(((Adubação!$B15-E6)*G6)/Adubação!$C15<0,0,((Adubação!$B15-E6)*G6)/Adubação!$C15),"S/ infos"),1))) | E15: =IFERROR(IF((I6/J6)>=3,"Dolomítico",IF((I6/J6)<=3,"Magnesiano","")),"") | F15: =IF(OR(B6=0,B6=""),"",ROUND(IFERROR((D15*C6),""),1)) | H15: =IFERROR(G15*F15,0) -> 0 | I15: =IFERROR(Adubação!$H15/C6,0) -> 0 | J15: =IF(Adubação!$D15="","",IF(Adubação!$F15=0,"Não precisa de calcário.",IF(Adubação!$D15>2,"Se o pasto já estiver formado, distribuir apenas 2 Ton/hectare de Calcário "&Adubação!$E15&". Se for incorporar, distribuir "&Adubação!$D15&" ton/ha. Pelo menos 60 dias antes do plantio ou das chuvas.","Distribuir "&Adubação!$D15&" Ton/hectare de Calcário "&Adubação!$E15&" pelo menos 60 dias antes do plantio ou início das chuvas.")))
D16: =IF(OR(B7=0,B7=""),"",IF(ROUND(IFERROR(IF(((Adubação!$B16-E7)*G7)/Adubação!$C16<0,0,((Adubação!$B16-E7)*G7)/Adubação!$C16),"S/ infos"),1)<1,0,ROUND(IFERROR(IF(((Adubação!$B16-E7)*G7)/Adubação!$C16<0,0,((Adubação!$B16-E7)*G7)/Adubação!$C16),"S/ infos"),1))) | E16: =IFERROR(IF((I7/J7)>=3,"Dolomítico",IF((I7/J7)<=3,"Magnesiano","")),"") | F16: =IF(OR(B7=0,B7=""),"",ROUND(IFERROR((D16*C7),""),1)) | H16: =IFERROR(G16*F16,0) -> 0 | I16: =IFERROR(Adubação!$H16/C7,0) -> 0 | J16: =IF(Adubação!$D16="","",IF(Adubação!$F16=0,"Não precisa de calcário.",IF(Adubação!$D16>2,"Se o pasto já estiver formado, distribuir apenas 2 Ton/hectare de Calcário "&Adubação!$E16&". Se for incorporar, distribuir "&Adubação!$D16&" ton/ha. Pelo menos 60 dias antes do plantio ou das chuvas.","Distribuir "&Adubação!$D16&" Ton/hectare de Calcário "&Adubação!$E16&" pelo menos 60 dias antes do plantio ou início das chuvas.")))
D17: =IF(OR(B8=0,B8=""),"",IF(ROUND(IFERROR(IF(((Adubação!$B17-E8)*G8)/Adubação!$C17<0,0,((Adubação!$B17-E8)*G8)/Adubação!$C17),"S/ infos"),1)<1,0,ROUND(IFERROR(IF(((Adubação!$B17-E8)*G8)/Adubação!$C17<0,0,((Adubação!$B17-E8)*G8)/Adubação!$C17),"S/ infos"),1))) | E17: =IFERROR(IF((I8/J8)>=3,"Dolomítico",IF((I8/J8)<=3,"Magnesiano","")),"") | F17: =IF(OR(B8=0,B8=""),"",ROUND(IFERROR((D17*C8),""),1)) | H17: =IFERROR(G17*F17,0) -> 0 | I17: =IFERROR(Adubação!$H17/C8,0) -> 0 | J17: =IF(Adubação!$D17="","",IF(Adubação!$F17=0,"Não precisa de calcário.",IF(Adubação!$D17>2,"Se o pasto já estiver formado, distribuir apenas 2 Ton/hectare de Calcário "&Adubação!$E17&". Se for incorporar, distribuir "&Adubação!$D17&" ton/ha. Pelo menos 60 dias antes do plantio ou das chuvas.","Distribuir "&Adubação!$D17&" Ton/hectare de Calcário "&Adubação!$E17&" pelo menos 60 dias antes do plantio ou início das chuvas.")))
D18: =IF(OR(B9=0,B9=""),"",IF(ROUND(IFERROR(IF(((Adubação!$B18-E9)*G9)/Adubação!$C18<0,0,((Adubação!$B18-E9)*G9)/Adubação!$C18),"S/ infos"),1)<1,0,ROUND(IFERROR(IF(((Adubação!$B18-E9)*G9)/Adubação!$C18<0,0,((Adubação!$B18-E9)*G9)/Adubação!$C18),"S/ infos"),1))) | E18: =IFERROR(IF((I9/J9)>=3,"Dolomítico",IF((I9/J9)<=3,"Magnesiano","")),"") | F18: =IF(OR(B9=0,B9=""),"",ROUND(IFERROR((D18*C9),""),1)) | H18: =IFERROR(G18*F18,0) -> 0 | I18: =IFERROR(Adubação!$H18/C9,0) -> 0 | J18: =IF(Adubação!$D18="","",IF(Adubação!$F18=0,"Não precisa de calcário.",IF(Adubação!$D18>2,"Se o pasto já estiver formado, distribuir apenas 2 Ton/hectare de Calcário "&Adubação!$E18&". Se for incorporar, distribuir "&Adubação!$D18&" ton/ha. Pelo menos 60 dias antes do plantio ou das chuvas.","Distribuir "&Adubação!$D18&" Ton/hectare de Calcário "&Adubação!$E18&" pelo menos 60 dias antes do plantio ou início das chuvas.")))
D19: =IF(OR(B10=0,B10=""),"",IF(ROUND(IFERROR(IF(((Adubação!$B19-E10)*G10)/Adubação!$C19<0,0,((Adubação!$B19-E10)*G10)/Adubação!$C19),"S/ infos"),1)<1,0,ROUND(IFERROR(IF(((Adubação!$B19-E10)*G10)/Adubação!$C19<0,0,((Adubação!$B19-E10)*G10)/Adubação!$C19),"S/ infos"),1))) | E19: =IFERROR(IF((I10/J10)>=3,"Dolomítico",IF((I10/J10)<=3,"Magnesiano","")),"") | F19: =IF(OR(B10=0,B10=""),"",ROUND(IFERROR((D19*C10),""),1)) | H19: =IFERROR(G19*F19,0) -> 0 | I19: =IFERROR(Adubação!$H19/C10,0) -> 0 | J19: =IF(Adubação!$D19="","",IF(Adubação!$F19=0,"Não precisa de calcário.",IF(Adubação!$D19>2,"Se o pasto já estiver formado, distribuir apenas 2 Ton/hectare de Calcário "&Adubação!$E19&". Se for incorporar, distribuir "&Adubação!$D19&" ton/ha. Pelo menos 60 dias antes do plantio ou das chuvas.","Distribuir "&Adubação!$D19&" Ton/hectare de Calcário "&Adubação!$E19&" pelo menos 60 dias antes do plantio ou início das chuvas.")))
B20: *se não encontrar o calcário correto que foi recomendado pela planilha, a segunda opção é calcário dolomítico, terceira magnesiano e quarta calcítico.
B22: Nitrogênio | F22: =SUM(F25:F29) -> 0 | H22: =SUM(H25:H29) -> 0
B24: % N na fonte | C24: Nome da fonte | D24: Rec. Kg/ha | E24: Ajustado (kg/ha) | F24: Total (ton) | G24: R$/kg | H24: R$ Total | I24: R$/ha | J24: Recomendação
D25: =IFERROR((IF(D6<=5,40,50))*D6/B25,"Falta %N") -> Falta %N | F25: =IFERROR(IF(OR(B$6=0,B$6=""),"",ROUND(IFERROR(((E25*C$6)/1000),""),1)),"") | H25: =IF(G25="","0",IFERROR(G25*E25*C6,"Falta R$/kg")) -> 0 | I25: =IFERROR(Adubação!$H25/C6,0) -> 0 | J25: =IF(Adubação!$D25=0,"",IF(Adubação!$E25>0,IFERROR("Parcelar a adubação em "&I30&" vezes, durante o período da chuva, sendo uma aplicação a cada "&ROUND(Adubação!M6/I30,0)&" dias, aplicando "&J30&" kg/ha de "&C25&" por aplicação.","Informações incompletas para gerar o relatório."),IFERROR("Parcelar a adubação em "&IF(#REF!>180,4,3)&" vezes, durante o período da chuva, aplicando "&ROUND(IF(#REF!>180,D25/4,D25/3),0)&" kg/ha de "&C25&" por aplicação.","Informações incompletas para gerar o relatório."))) -> Informações incompletas para gerar o relatório.
D26: =IFERROR((IF(D7<=5,40,50))*D7/B26,"Falta %N") -> Falta %N | F26: =IFERROR(IF(OR(B$6=0,B$6=""),"",ROUND(IFERROR(((E26*C$6)/1000),""),1)),"") | H26: =IF(G26="","0",IFERROR(G26*E26*C7,"Falta R$/kg")) -> 0 | I26: =IFERROR(Adubação!$H26/C7,0) -> 0 | J26: =IF(Adubação!$D26=0,"",IF(Adubação!$E26>0,IFERROR("Parcelar a adubação em "&I31&" vezes, durante o período da chuva, sendo uma aplicação a cada "&ROUND(Adubação!M7/I31,0)&" dias, aplicando "&J31&" kg/ha de "&C26&" por aplicação.","Informações incompletas para gerar o relatório."),IFERROR("Parcelar a adubação em "&IF(#REF!>180,4,3)&" vezes, durante o período da chuva, aplicando "&ROUND(IF(#REF!>180,D26/4,D26/3),0)&" kg/ha de "&C26&" por aplicação.","Informações incompletas para gerar o relatório."))) -> Informações incompletas para gerar o relatório.
D27: =IFERROR((IF(D8<=5,40,50))*D8/B27,"Falta %N") -> Falta %N | F27: =IFERROR(IF(OR(B$6=0,B$6=""),"",ROUND(IFERROR(((E27*C$6)/1000),""),1)),"") | H27: =IF(G27="","0",IFERROR(G27*E27*C8,"Falta R$/kg")) -> 0 | I27: =IFERROR(Adubação!$H27/C8,0) -> 0 | J27: =IF(Adubação!$D27=0,"",IF(Adubação!$E27>0,IFERROR("Parcelar a adubação em "&I32&" vezes, durante o período da chuva, sendo uma aplicação a cada "&ROUND(Adubação!M8/I32,0)&" dias, aplicando "&J32&" kg/ha de "&C27&" por aplicação.","Informações incompletas para gerar o relatório."),IFERROR("Parcelar a adubação em "&IF(#REF!>180,4,3)&" vezes, durante o período da chuva, aplicando "&ROUND(IF(#REF!>180,D27/4,D27/3),0)&" kg/ha de "&C27&" por aplicação.","Informações incompletas para gerar o relatório."))) -> Informações incompletas para gerar o relatório.
D28: =IFERROR((IF(D9<=5,40,50))*D9/B28,"Falta %N") -> Falta %N | F28: =IFERROR(IF(OR(B$6=0,B$6=""),"",ROUND(IFERROR(((E28*C$6)/1000),""),1)),"") | H28: =IF(G28="","0",IFERROR(G28*E28*C9,"Falta R$/kg")) -> 0 | I28: =IFERROR(Adubação!$H28/C9,0) -> 0 | J28: =IF(Adubação!$D28=0,"",IF(Adubação!$E28>0,IFERROR("Parcelar a adubação em "&I33&" vezes, durante o período da chuva, sendo uma aplicação a cada "&ROUND(Adubação!M9/I33,0)&" dias, aplicando "&J33&" kg/ha de "&C28&" por aplicação.","Informações incompletas para gerar o relatório."),IFERROR("Parcelar a adubação em "&IF(#REF!>180,4,3)&" vezes, durante o período da chuva, aplicando "&ROUND(IF(#REF!>180,D28/4,D28/3),0)&" kg/ha de "&C28&" por aplicação.","Informações incompletas para gerar o relatório."))) -> Informações incompletas para gerar o relatório.
D29: =IFERROR((IF(D10<=5,40,50))*D10/B29,"Falta %N") -> Falta %N | F29: =IFERROR(IF(OR(B$6=0,B$6=""),"",ROUND(IFERROR(((E29*C$6)/1000),""),1)),"") | H29: =IF(G29="","0",IFERROR(G29*E29*C10,"Falta R$/kg")) -> 0 | I29: =IFERROR(Adubação!$H29/C10,0) -> 0 | J29: =IF(Adubação!$D29=0,"",IF(Adubação!$E29>0,IFERROR("Parcelar a adubação em "&I34&" vezes, durante o período da chuva, sendo uma aplicação a cada "&ROUND(Adubação!M10/I34,0)&" dias, aplicando "&J34&" kg/ha de "&C29&" por aplicação.","Informações incompletas para gerar o relatório."),IFERROR("Parcelar a adubação em "&IF(#REF!>180,4,3)&" vezes, durante o período da chuva, aplicando "&ROUND(IF(#REF!>180,D29/4,D29/3),0)&" kg/ha de "&C29&" por aplicação.","Informações incompletas para gerar o relatório."))) -> Informações incompletas para gerar o relatório.
B30: *se você usar um formulado que tem potássio na sua composição, precisa ser descontado na hora da adubação de potássio. | I30: =ROUND((B25*D25)/50,0) -> #VALUE! | J30: =ROUNDUP((E25/I30),0) -> #VALUE!
B31: *para lotações acima de 5 U.A/ha, para cada 10 Kg de nitrogênio aplicado, distribuir 1 kg de Enxofre. | I31: =ROUND((B26*D26)/50,0) -> #VALUE! | J31: =ROUNDUP((E26/I31),0) -> #VALUE!
I32: =ROUND((B27*D27)/50,0) -> #VALUE! | J32: =ROUNDUP((E27/I32),0) -> #VALUE!
I33: =ROUND((B28*D28)/50,0) -> #VALUE! | J33: =ROUNDUP((E28/I33),0) -> #VALUE!
I34: =ROUND((B29*D29)/50,0) -> #VALUE! | J34: =ROUNDUP((E29/I34),0) -> #VALUE!
B37: Fósforo | F37: =SUM(F40:F44) -> 0 | H37: =SUM(H40:H44) -> 0
B39: %P fonte | C39: Nome da fonte | D39: Rec. Kg/ha | E39: Ajustado (kg/ha) | F39: Total (ton) | G39: R$/kg | H39: R$ Total | I39: R$/ha | J39: Recomendação
D40: =IF(B40="","Falta %P",IF(L6>300,(((MAX(0,(5+(2*D6)-K6)*10))/B40)*1.3),(MAX(0,(5+(2*D6)-K6)*10))/B40)) -> Falta %P | F40: =IFERROR(IF(OR(B$6=0,B$6=""),"",ROUND(IFERROR(((E40*C$6)/1000),""),1)),"") | H40: =IF(Adubação!$G40="",0,G40*E40*C6) -> 0 | I40: =IFERROR(IF(Adubação!$G40="",0,H40/C6),0) -> 0 | J40: =IF(OR(Adubação!$C40="",Adubação!$B40="",Adubação!$E40=""),"Informações incompletas para gerar o relatório.",IF(F6>=0.1,"Como o M% (Sat/Al) está alto, é preciso realizar a calagem obrigatoriamente antes da fosfatagem! De 60 a 90 dias (c/ chuva) após a calagem, distribuir "&E40&" kg/ha de "&C40&". Pode ser distribuído antes, junto ou logo depois da semente, no caso de reforma, ou por cobertura no pasto já formado.","Em reformas, distribuir antes, junto ou logo depois da semente. Em pasto formado, distribua em cobertura, no início do período das águas "&E40&" kg/ha de "&C40&".")) -> Informações incompletas para gerar o relatório.
D41: =IF(B41="","Falta %P",IF(L7>300,(((MAX(0,(5+(2*D7)-K7)*10))/B41)*1.3),(MAX(0,(5+(2*D7)-K7)*10))/B41)) -> Falta %P | F41: =IFERROR(IF(OR(B$6=0,B$6=""),"",ROUND(IFERROR(((E41*C$6)/1000),""),1)),"") | H41: =IF(Adubação!$G41="",0,G41*E41*C7) -> 0 | I41: =IFERROR(IF(Adubação!$G41="",0,H41/C7),0) -> 0 | J41: =IF(OR(Adubação!$C41="",Adubação!$B41="",Adubação!$E41=""),"Informações incompletas para gerar o relatório.",IF(F7>=0.1,"Como o M% (Sat/Al) está alto, é preciso realizar a calagem obrigatoriamente antes da fosfatagem! De 60 a 90 dias (c/ chuva) após a calagem, distribuir "&E41&" kg/ha de "&C41&". Pode ser distribuído antes, junto ou logo depois da semente, no caso de reforma, ou por cobertura no pasto já formado.","Em reformas, distribuir antes, junto ou logo depois da semente. Em pasto formado, distribua em cobertura, no início do período das águas "&E41&" kg/ha de "&C41&".")) -> Informações incompletas para gerar o relatório.
D42: =IF(B42="","Falta %P",IF(L8>300,(((MAX(0,(5+(2*D8)-K8)*10))/B42)*1.3),(MAX(0,(5+(2*D8)-K8)*10))/B42)) -> Falta %P | F42: =IFERROR(IF(OR(B$6=0,B$6=""),"",ROUND(IFERROR(((E42*C$6)/1000),""),1)),"") | H42: =IF(Adubação!$G42="",0,G42*E42*C8) -> 0 | I42: =IFERROR(IF(Adubação!$G42="",0,H42/C8),0) -> 0 | J42: =IF(OR(Adubação!$C42="",Adubação!$B42="",Adubação!$E42=""),"Informações incompletas para gerar o relatório.",IF(F8>=0.1,"Como o M% (Sat/Al) está alto, é preciso realizar a calagem obrigatoriamente antes da fosfatagem! De 60 a 90 dias (c/ chuva) após a calagem, distribuir "&E42&" kg/ha de "&C42&". Pode ser distribuído antes, junto ou logo depois da semente, no caso de reforma, ou por cobertura no pasto já formado.","Em reformas, distribuir antes, junto ou logo depois da semente. Em pasto formado, distribua em cobertura, no início do período das águas "&E42&" kg/ha de "&C42&".")) -> Informações incompletas para gerar o relatório.
D43: =IF(B43="","Falta %P",IF(L9>300,(((MAX(0,(5+(2*D9)-K9)*10))/B43)*1.3),(MAX(0,(5+(2*D9)-K9)*10))/B43)) -> Falta %P | F43: =IFERROR(IF(OR(B$6=0,B$6=""),"",ROUND(IFERROR(((E43*C$6)/1000),""),1)),"") | H43: =IF(Adubação!$G43="",0,G43*E43*C9) -> 0 | I43: =IFERROR(IF(Adubação!$G43="",0,H43/C9),0) -> 0 | J43: =IF(OR(Adubação!$C43="",Adubação!$B43="",Adubação!$E43=""),"Informações incompletas para gerar o relatório.",IF(F9>=0.1,"Como o M% (Sat/Al) está alto, é preciso realizar a calagem obrigatoriamente antes da fosfatagem! De 60 a 90 dias (c/ chuva) após a calagem, distribuir "&E43&" kg/ha de "&C43&". Pode ser distribuído antes, junto ou logo depois da semente, no caso de reforma, ou por cobertura no pasto já formado.","Em reformas, distribuir antes, junto ou logo depois da semente. Em pasto formado, distribua em cobertura, no início do período das águas "&E43&" kg/ha de "&C43&".")) -> Informações incompletas para gerar o relatório.
D44: =IF(B44="","Falta %P",IF(L10>300,(((MAX(0,(5+(2*D10)-K10)*10))/B44)*1.3),(MAX(0,(5+(2*D10)-K10)*10))/B44)) -> Falta %P | F44: =IFERROR(IF(OR(B$6=0,B$6=""),"",ROUND(IFERROR(((E44*C$6)/1000),""),1)),"") | H44: =IF(Adubação!$G44="",0,G44*E44*C10) -> 0 | I44: =IFERROR(IF(Adubação!$G44="",0,H44/C10),0) -> 0 | J44: =IF(OR(Adubação!$C44="",Adubação!$B44="",Adubação!$E44=""),"Informações incompletas para gerar o relatório.",IF(F10>=0.1,"Como o M% (Sat/Al) está alto, é preciso realizar a calagem obrigatoriamente antes da fosfatagem! De 60 a 90 dias (c/ chuva) após a calagem, distribuir "&E44&" kg/ha de "&C44&". Pode ser distribuído antes, junto ou logo depois da semente, no caso de reforma, ou por cobertura no pasto já formado.","Em reformas, distribuir antes, junto ou logo depois da semente. Em pasto formado, distribua em cobertura, no início do período das águas "&E44&" kg/ha de "&C44&".")) -> Informações incompletas para gerar o relatório.
B45: *se for usar um adubo de rápida liberação, como por exemplo o MAP, é recomendável parcelar quando a recomendação for acima de 300kg/ha. Em 2x é suficiente, sendo uma no início e outra no meio da chuva.
B47: Potássio | F47: =SUM(F50:F54) -> 0 | H47: =SUM(H50:H54) -> 0
B49: %K fonte | C49: Nome da fonte | D49: Kg/ha | E49: Ajustado (kg/ha) | F49: Total (ton) | G49: R$/kg | H49: R$ Total | I49: R$/ha | J49: Recomendação
D50: =IF(B50="","Falta %K", IFERROR((IF((3+(D6-1)*0.6-H6)*(G6/10)*100<0,0,(3+(D6-1)*0.6-H6)*(G6/10)*100))/B50,0)) -> Falta %K | F50: =IFERROR(IF(OR(B$6=0,B$6=""),"",ROUND(IFERROR(((E50*C$6)/1000),""),1)),"") | H50: =IF(Adubação!$G50="",0,IFERROR((G50*E50*C6),"Falta Kg/ha")) -> 0 | I50: =IF(Adubação!$G50="",0,IFERROR(G50*D50,0)) -> 0 | J50: =IF(AND(Adubação!$E50="",Adubação!$C50=""),"Informações incompletas para gerar o relatório.",IF(Adubação!$E50="Falta %K","Informações incompletas para gerar o relatório.",IF(Adubação!$E50=0,"Não precisa realizar adubação de potássio",IF(Adubação!$E50<=120,"Parcelar a adubação em 2x de "&ROUND(Adubação!$E50/2,0)&"kg/ha de "&Adubação!$C50&" em períodos equidistantes na época da chuva. Se possível, adubar próximo a adubação de N.",IF(AND(Adubação!$E50>120,Adubação!$E50<=240),"Parcelar a adubação em 3x de "&ROUND(Adubação!$E50/3,0)&"kg/ha de "&Adubação!$C50&" em períodos equidistantes na época da chuva. Se possível, adubar próximo a adubação de N.","Parcelar a adubação em 4x de "&ROUND(Adubação!$E50/4,0)&"kg/ha de "&Adubação!$C50&" em períodos equidistantes na época da chuva. Se possível, adubar próximo a adubação de N."))))) -> Informações incompletas para gerar o relatório.
D51: =IF(B51="","Falta %K", IFERROR((IF((3+(D7-1)*0.6-H7)*(G7/10)*100<0,0,(3+(D7-1)*0.6-H7)*(G7/10)*100))/B51,0)) -> Falta %K | F51: =IFERROR(IF(OR(B$6=0,B$6=""),"",ROUND(IFERROR(((E51*C$6)/1000),""),1)),"") | H51: =IF(Adubação!$G51="",0,IFERROR((G51*E51*C7),"Falta Kg/ha")) -> 0 | I51: =IF(Adubação!$G51="",0,IFERROR(G51*D51,0)) -> 0 | J51: =IF(AND(Adubação!$E51="",Adubação!$C51=""),"Informações incompletas para gerar o relatório.",IF(Adubação!$E51="Falta %K","Informações incompletas para gerar o relatório.",IF(Adubação!$E51=0,"Não precisa realizar adubação de potássio",IF(Adubação!$E51<=120,"Parcelar a adubação em 2x de "&ROUND(Adubação!$E51/2,0)&"kg/ha de "&Adubação!$C51&" em períodos equidistantes na época da chuva. Se possível, adubar próximo a adubação de N.",IF(AND(Adubação!$E51>120,Adubação!$E51<=240),"Parcelar a adubação em 3x de "&ROUND(Adubação!$E51/3,0)&"kg/ha de "&Adubação!$C51&" em períodos equidistantes na época da chuva. Se possível, adubar próximo a adubação de N.","Parcelar a adubação em 4x de "&ROUND(Adubação!$E51/4,0)&"kg/ha de "&Adubação!$C51&" em períodos equidistantes na época da chuva. Se possível, adubar próximo a adubação de N."))))) -> Informações incompletas para gerar o relatório.
D52: =IF(B52="","Falta %K", IFERROR((IF((3+(D8-1)*0.6-H8)*(G8/10)*100<0,0,(3+(D8-1)*0.6-H8)*(G8/10)*100))/B52,0)) -> Falta %K | F52: =IFERROR(IF(OR(B$6=0,B$6=""),"",ROUND(IFERROR(((E52*C$6)/1000),""),1)),"") | H52: =IF(Adubação!$G52="",0,IFERROR((G52*E52*C8),"Falta Kg/ha")) -> 0 | I52: =IF(Adubação!$G52="",0,IFERROR(G52*D52,0)) -> 0 | J52: =IF(AND(Adubação!$E52="",Adubação!$C52=""),"Informações incompletas para gerar o relatório.",IF(Adubação!$E52="Falta %K","Informações incompletas para gerar o relatório.",IF(Adubação!$E52=0,"Não precisa realizar adubação de potássio",IF(Adubação!$E52<=120,"Parcelar a adubação em 2x de "&ROUND(Adubação!$E52/2,0)&"kg/ha de "&Adubação!$C52&" em períodos equidistantes na época da chuva. Se possível, adubar próximo a adubação de N.",IF(AND(Adubação!$E52>120,Adubação!$E52<=240),"Parcelar a adubação em 3x de "&ROUND(Adubação!$E52/3,0)&"kg/ha de "&Adubação!$C52&" em períodos equidistantes na época da chuva. Se possível, adubar próximo a adubação de N.","Parcelar a adubação em 4x de "&ROUND(Adubação!$E52/4,0)&"kg/ha de "&Adubação!$C52&" em períodos equidistantes na época da chuva. Se possível, adubar próximo a adubação de N."))))) -> Informações incompletas para gerar o relatório.
D53: =IF(B53="","Falta %K", IFERROR((IF((3+(D9-1)*0.6-H9)*(G9/10)*100<0,0,(3+(D9-1)*0.6-H9)*(G9/10)*100))/B53,0)) -> Falta %K | F53: =IFERROR(IF(OR(B$6=0,B$6=""),"",ROUND(IFERROR(((E53*C$6)/1000),""),1)),"") | H53: =IF(Adubação!$G53="",0,IFERROR((G53*E53*C9),"Falta Kg/ha")) -> 0 | I53: =IF(Adubação!$G53="",0,IFERROR(G53*D53,0)) -> 0 | J53: =IF(AND(Adubação!$E53="",Adubação!$C53=""),"Informações incompletas para gerar o relatório.",IF(Adubação!$E53="Falta %K","Informações incompletas para gerar o relatório.",IF(Adubação!$E53=0,"Não precisa realizar adubação de potássio",IF(Adubação!$E53<=120,"Parcelar a adubação em 2x de "&ROUND(Adubação!$E53/2,0)&"kg/ha de "&Adubação!$C53&" em períodos equidistantes na época da chuva. Se possível, adubar próximo a adubação de N.",IF(AND(Adubação!$E53>120,Adubação!$E53<=240),"Parcelar a adubação em 3x de "&ROUND(Adubação!$E53/3,0)&"kg/ha de "&Adubação!$C53&" em períodos equidistantes na época da chuva. Se possível, adubar próximo a adubação de N.","Parcelar a adubação em 4x de "&ROUND(Adubação!$E53/4,0)&"kg/ha de "&Adubação!$C53&" em períodos equidistantes na época da chuva. Se possível, adubar próximo a adubação de N."))))) -> Informações incompletas para gerar o relatório.
D54: =IF(B54="","Falta %K", IFERROR((IF((3+(D10-1)*0.6-H10)*(G10/10)*100<0,0,(3+(D10-1)*0.6-H10)*(G10/10)*100))/B54,0)) -> Falta %K | F54: =IFERROR(IF(OR(B$6=0,B$6=""),"",ROUND(IFERROR(((E54*C$6)/1000),""),1)),"") | H54: =IF(Adubação!$G54="",0,IFERROR((G54*E54*C10),"Falta Kg/ha")) -> 0 | I54: =IF(Adubação!$G54="",0,IFERROR(G54*D54,0)) -> 0 | J54: =IF(AND(Adubação!$E54="",Adubação!$C54=""),"Informações incompletas para gerar o relatório.",IF(Adubação!$E54="Falta %K","Informações incompletas para gerar o relatório.",IF(Adubação!$E54=0,"Não precisa realizar adubação de potássio",IF(Adubação!$E54<=120,"Parcelar a adubação em 2x de "&ROUND(Adubação!$E54/2,0)&"kg/ha de "&Adubação!$C54&" em períodos equidistantes na época da chuva. Se possível, adubar próximo a adubação de N.",IF(AND(Adubação!$E54>120,Adubação!$E54<=240),"Parcelar a adubação em 3x de "&ROUND(Adubação!$E54/3,0)&"kg/ha de "&Adubação!$C54&" em períodos equidistantes na época da chuva. Se possível, adubar próximo a adubação de N.","Parcelar a adubação em 4x de "&ROUND(Adubação!$E54/4,0)&"kg/ha de "&Adubação!$C54&" em períodos equidistantes na época da chuva. Se possível, adubar próximo a adubação de N."))))) -> Informações incompletas para gerar o relatório.
B55: *pode acontecer de pedir muito potássio, caso a CTC do seu solo seja alta. Não precisa necessariamente corrigir todo o potássio em um ano só, pode trabalhar com um "limite" de 200 kg de K por ano.
B57: Micro nutrientes
...

Sheet Dimensionamento de água
B1: PLANILHA PARA DIMENSIONAMENTO DO SISTEMA DE ÁGUA
B3: INFORMAÇÕES DO SISTEMA | L3: L/H | M3: 25 | N3: 32 | O3: 40 | P3: 50 | Q3: 75 | R3: 100 | S3: 125 | T3: 150 | U3: 200 | V3: 250 | W3: 300 | AB3: DADOS GEOMÉTRICOS DA INSTALAÇÃO | AD3: L (m)
B4: Qnt. Cabeças | K4: 1 | L4: 498 | M4: 0.7 | N4: 0.2 | O4: 0 | X4: 1 | AB4: A | AD4: 0
B5: Tempo de bombeamento (horas) | K5: 2 | L5: 1002 | M5: 2.7 | N5: 0.75 | O5: 0.22 | P5: 0.08 | X5: 2 | AB5: B | AD5: 0
B6: Dias p/ manutenção | K6: 3 | L6: 1500 | M6: 6 | N6: 1.6 | O6: 0.5 | P6: 0.17 | X6: 3 | AB6: C | AD6: ='Dimensionamento de água'!C13 -> 0
B7: Potência bomba (cv) | C7: =ROUNDUP(AC39/735,0) -> #DIV/0! | K7: 4 | L7: 1998 | M7: 10 | N7: 2.7 | O7: 0.8 | P7: 0.28 | X7: 4 | AB7: D | AD7: ='Dimensionamento de água'!C14 -> 0
B8: Tamanho reservatório (L) | C8: =C6*C4*60 -> 0 | K8: 5 | L8: 3000 | M8: 21.5 | N8: 6 | O8: 1.8 | P8: 0.6 | Q8: 0.05 | X8: 5 | AB8: E | AD8: 3
K9: 6 | L9: 4002 | M9: 27 | N9: 10 | O9: 3 | P9: 1.05 | Q9: 0.1 | X9: 6 | AB9: F | AD9: 2
B10: LINHA DE CAPTAÇÃO | K10: 7 | L10: 4998 | M10: 55 | N10: 15.5 | O10: 4.7 | P10: 1.6 | Q10: 0.15 | R10: 0.05 | X10: 7 | AB10: H | AD10: =AD6+AD8+AD4 -> 3
B11: Altitude Inicial (m) | D11: =IFERROR(IF(C16=0,"Diminuir o diâmetro",IF(C17<=1.5,"Aumentar diâmetro ou altitude","Ok")),"Pode diminuir o diâmetro") -> Pode diminuir o diâmetro | K11: 8 | L11: 6000 | M11: 60 | N11: 22 | O11: 6.6 | P11: 2.2 | Q11: 0.2 | R11: 0.07 | X11: 8 | AB11: ACESSÓRIOS | AC11: QUANT. | AD11: L EQ (m)
B12: Altitude reservatório (m) | K12: 9 | L12: 7998 | N12: 37 | O12: 11.5 | P12: 3.9 | Q12: 0.35 | R12: 0.13 | X12: 9 | AB12: CURVA DE 90 graus | AC12: 4 | AD12: =AC12*((0.786*LN(AC21))-1.845) -> #NUM!
B13: Dif. Nível (m) | C13: =(C11-C12)*-1 -> 0 | K13: 10 | L13: 10002 | N13: 56 | O13: 17 | P13: 5.7 | Q13: 0.5 | R13: 0.2 | S13: 0.06 | X13: 10 | AB13: VÁLVULA DE RETENÇÃO | AC13: 1 | AD13: =AC13*(0.12449*AC21-0.01819) -> -0.01819
B14: Comprimento (m) | K14: 11 | L14: 12498 | N14: 85 | O14: 26 | P14: 8.5 | Q14: 0.8 | R14: 0.28 | S14: 0.09 | X14: 11 | AB14: VÁLVULA DE PÉ OU CRIVO | AC14: 1 | AD14: =AC14*(15.3311*LN(AC21)-36.98) -> #NUM!
B15: Diâmetro (mm) | K15: 12 | L15: 15000 | O15: 37 | P15: 12.5 | Q15: 1.1 | R15: 0.4 | S15: 0.13 | T15: 0.05 | X15: 12 | AB15: SAÍDA DA TUBULAÇÃO | AC15: 3 | AD15: =2.21*LN(AC21)-5.559 -> #NUM!
B16: Perda (m) | C16: =HLOOKUP(C15,'Dimensionamento de água'!$L$3:$W$45,VLOOKUP(VLOOKUP((C4*50)/C5,'Dimensionamento de água'!$L$4:$L$45,1,1),'Dimensionamento de água'!$L$4:$X$45,13,0)+2,0)*(C14/100) -> #DIV/0! | K16: 13 | L16: 17502 | O16: 47 | P16: 16 | Q16: 1.4 | R16: 0.5 | S16: 0.17 | T16: 0.06 | X16: 13 | AB16: REGISTRO DE GLOBO | AC16: 0 | AD16: =AC16*(0.3269*AC21+0.6384) -> 0
B17: Pressão final (MCA) | C17: =C13-C16 -> #DIV/0! | K17: 14 | L17: 19998 | O17: 63 | P17: 21.5 | Q17: 2 | R17: 0.7 | S17: 0.23 | T17: 0.09 | X17: 14 | AB17: REGISTRO DE GAVETA | AC17: 0 | AD17: =AC17*(0.5269*LN(AC21)-1.3735) -> #NUM!
B18: PN (mínimo) | C18: =(C17+C16)*1.3 -> #DIV/0! | K18: 15 | L18: 25002 | O18: 95 | P18: 33 | Q18: 3 | R18: 1.1 | S18: 0.35 | T18: 0.13 | X18: 15 | AB18: DADOS DO ESCOAMENTO
K19: 16 | L19: 30000 | P19: 45 | Q19: 4.2 | R19: 1.5 | S19: 0.5 | T19: 0.2 | U19: 0.05 | X19: 16 | AB19: VAZÃO DA BOMBA | AC19: =('Dimensionamento de água'!C4*50)/'Dimensionamento de água'!C5/60/60 -> #DIV/0! | AD19: LITROS/SEG
B20: LINHA DE DISTRIBUIÇÃO | K20: 17 | L20: 34998 | P20: 61 | Q20: 5.7 | R20: 2 | S20: 0.65 | T20: 0.24 | U20: 0.06 | X20: 17 | AB20: VAZÃO DA BOMBA | AC20: =AC19/1000 -> #DIV/0! | AD20: m³/s
B21: Altitude Inicial (m) | C21: =C12 -> 0 | D21: =IFERROR(IF(C26=0,"Corrigir o diâmetro",IF(C27<=1.5,"Aumentar diâmetro","Ok")),"Pode diminuir o diâmetro") -> Pode diminuir o diâmetro | K21: 18 | L21: 40002 | P21: 78 | Q21: 7 | R21: 2.5 | S21: 0.8 | T21: 0.3 | U21: 0.08 | X21: 18 | AB21: DIÂMETRO DA CANALIZAÇÃO | AC21: ='Dimensionamento de água'!C15 -> 0 | AD21: mm
B22: Altitude Final (m) | K22: 19 | L22: 45000 | P22: 100 | Q22: 9 | R22: 3.1 | S22: 1 | T22: 0.4 | U22: 0.1 | X22: 19 | AB22: DIÂMETRO DA CANALIZAÇÃO EM METROS | AC22: =AC21/1000 -> 0 | AD22: m
B23: Dif. Nível (m) | C23: =C21-C22 -> 0 | K23: 20 | L23: 49998 | Q23: 11 | R23: 3.8 | S23: 1.25 | T23: 0.5 | U23: 0.12 | X23: 20 | AB23: PROPRIEDADES DA ÁGUA
B24: Comprimento (m) | K24: 21 | L24: 60000 | Q24: 16 | R24: 5.5 | S24: 1.8 | T24: 0.7 | U24: 0.16 | V24: 0.05 | X24: 21 | AB24: VISCOSIDADE | AC24: 1.127e-06 | AD24: m²/s
B25: Diâmetro (mm) | K25: 22 | L25: 70002 | Q25: 21 | R25: 7.2 | S25: 2.4 | T25: 0.9 | U25: 0.21 | V25: 0.07 | X25: 22 | AB25: DENSIDADE | AC25: 1000 | AD25: kg/m³
B26: Perda (m) | C26: =HLOOKUP(C25,'Dimensionamento de água'!$L$3:$W$45,VLOOKUP(VLOOKUP((C4*50)/12,'Dimensionamento de água'!$L$4:$L$45,1,1),'Dimensionamento de água'!$L$4:$X$45,13,0)+2,0)*(C24/100) -> #N/A | K26: 23 | L26: 79998 | Q26: 26.5 | R26: 9.2 | S26: 3.1 | T26: 1.2 | U26: 0.27 | V26: 0.09 | X26: 23 | AB26: TEMPERATURA | AC26: 25 | AD26: oC
B27: Pressão final (MCA) | C27: =C23-C26 -> #N/A | K27: 24 | L27: 90000 | Q27: 34 | R27: 12 | S27: 3.8 | T27: 1.4 | U27: 0.35 | V27: 0.12 | X27: 24 | AB27: CÁLCULOS GERAIS
B28: PN (mínimo) | C28: =(C27+C26)*1.3 -> #N/A | K28: 25 | L28: 100002 | Q28: 40 | R28: 14 | S28: 4.7 | T28: 1.8 | U28: 0.42 | V28: 0.14 | X28: 25 | AB28: VELOCIDADE DO ESCOAMENTO | AC28: =AC20/AC29 -> #DIV/0! | AD28: m/s
K29: 26 | L29: 120000 | Q29: 58 | R29: 20 | S29: 6.6 | T29: 2.5 | U29: 0.6 | V29: 0.2 | W29: 0.08 | X29: 26 | AB29: ÁREA INTERNA DA TUBULAÇÃO | AC29: =(3.14*AC22^2)/4 -> 0 | AD29: m²
K30: 27 | L30: 139998 | Q30: 80 | R30: 27 | S30: 9 | T30: 3.3 | U30: 0.8 | V30: 0.26 | W30: 0.1 | X30: 27 | AB30: NÚMERO DE REYNOLDS | AC30: =AC28*AC22/0.000001127 -> #DIV/0!
B31: Tamanho bebedouro (m) | C31: =C4*0.05 -> 0 | K31: 28 | L31: 160002 | R31: 35 | S31: 11.5 | T31: 4.25 | U31: 1 | V31: 0.34 | W31: 0.13 | X31: 28 | AB31: FATOR DE ATRITO (D.MOODY) | AC31: =0.222554*AC30^-0.216968 -> #DIV/0!
B32: Se beber dos dois lados | C32: =C31/2 -> 0 | K32: 29 | L32: 180000 | R32: 43 | S32: 14 | T32: 5.3 | U32: 1.25 | V32: 0.42 | W32: 0.17 | X32: 29 | AB32: COMPRIMENTO DE TRECHO RETO DE TUBO | AC32: =AD4+AD5+AD6+AD7+AD8+AD9 -> 5 | AD32: m
K33: 30 | L33: 199998 | R33: 50 | S33: 17.5 | T33: 6.5 | U33: 1.5 | V33: 0.5 | W33: 0.2 | X33: 30 | AB33: COMPRIMENTO EQUIVALENTE DE TUBO | AC33: =AD12+AD13+AD14+AD15+AD16+AD17 -> #NUM! | AD33: m
K34: 31 | L34: 250002 | R34: 80 | S34: 26.5 | T34: 10 | U34: 2.3 | V34: 0.8 | W34: 0.32 | X34: 31 | AB34: COMPRIMENTO TOTAL DE TUBULAÇÃO | AC34: =AC32+AC33 -> #NUM! | AD34: m
K35: 32 | L35: 300000 | S35: 36 | T35: 14 | U35: 3.3 | V35: 1.1 | W35: 0.45 | X35: 32 | AB35: VARIAÇÃO DE ENERGIA (DELTA E) | AC35: =AC31*AC34*AC28*AC28/(2*AC22) -> #DIV/0! | AD35: m²/s²
K36: 33 | L36: 349998 | T36: 19 | U36: 4.5 | V36: 1.5 | W36: 0.6 | X36: 33 | AB36: ALTURA MANOMÉTRICA (m) | AC36: =(AC35/9.81)+AD10 -> #DIV/0! | AD36: m
K37: 34 | L37: 400002 | T37: 24 | U37: 5.8 | V37: 1.9 | W37: 0.8 | X37: 34 | AB37: EFICIÊNCIA DA BOMBA | AC37: 0.7
K38: 35 | L38: 450000 | U38: 7 | V38: 2.4 | W38: 1 | X38: 35 | AB38: POTÊNCIA TEÓRICA DA BOMBA (W) | AC38: =AC19*(((AC28^2)/2)+(9.81*AD10)+(AC35)) -> #DIV/0! | AD38: w
K39: 36 | L39: 499998 | U39: 8.5 | V39: 2.9 | W39: 1.2 | X39: 36 | AB39: POTÊNCIA DE ACIONAMENTO (W) | AC39: =AC38/AC37 -> #DIV/0! | AD39: w
K40: 37 | L40: 550002 | U40: 10.2 | V40: 3.5 | W40: 1.5 | X40: 37
K41: 38 | L41: 600000 | U41: 12 | V41: 4.1 | W41: 1.75 | X41: 38
...

Sheet Formulação de suplemento
C1: PLANILHA PARA FORMULAÇÃO DE SUPLEMENTOS PARA BOVINOS A PASTO
FD3: 180 | FN3: 300 | FW3: 300 | GO3: Categoria | GP3: Ingrediente | GQ3: MS (%) | GR3: EE (%MS) | GS3: PB (%MS) | GT3: NDT (%MS) | GU3: FDN (%MS) | GV3: Ca (%MS) | GW3: P (%MS) | GX3: Mg (%MS) | GY3: K (%MS) | GZ3: Na (%MS) | HA3: S (%MS) | HB3: Co (mg/kg) | HC3: Cu (mg/kg) | HD3: Mn (mg/kg) | HE3: Se (mg/kg) | HF3: Zn (mg/kg)
FD4: Exigência | FE4: Código | FF4: Unidade | FG4: Mínimo | FH4: Ideal | FI4: Máximo | FN4: Exigência | FO4: Código | FP4: Unidade | FQ4: Mínimo | FR4: Ideal | FS4: Máximo | FW4: Exigência | FX4: Código | FY4: Unidade | FZ4: Mínimo | GA4: Ideal | GB4: Máximo | GO4: Forragens Verdes | GP4: Cana-de-açúcar | GQ4: 27.53 | GR4: 1.46 | GS4: 2.86 | GT4: 63.48 | GU4: 49.49 | GV4: 0.24 | GW4: 0.08 | GX4: 0.18 | GY4: 0.68 | GZ4: 0.03 | HA4: 0.06 | HB4: 0.54 | HC4: 5.85 | HD4: 49.57 | HF4: 21.18
B5: INFORMAÇÕES P/ EXIGÊNCIA | E5: FORMULAÇÃO DO SUPLEMENTO | J5: EXIGÊNCIA x DIETA | R5: RESUMO DA DIETA GERAL | Z5: OUTRAS INFORMAÇÕES | AH5: Ingr | AK5: Capim | FD5: Matéria Seca | FE5: MS | FF5: kg/dia | FH5: 5.5 | FI5: 6.05 | FJ5: =FI5/FH5 -> 1.1 | FN5: Matéria Seca | FO5: MS | FP5: kg/dia | FR5: 6.85 | FS5: 7.53 | FT5: =FS5/FR5 -> 1.0992701 | FW5: Matéria Seca | FX5: MS | FY5: kg/dia | GA5: 6.85 | GB5: 7.53 | GC5: =GB5/GA5 -> 1.0992701 | GO5: Forragens Verdes | GP5: Capim Andropogon | GQ5: 25.55 | GR5: 2.15 | GS5: 4.49 | GT5: 53.56 | GU5: 70.13 | GV5: 0.04
B6: Peso inicial (kg) | E6: Ingrediente | F6: % | G6: R$/kg | H6: R$ | J6: Descrição | K6: Ideal | L6: Máximo | M6: Dieta | N6: Resultado | O6: % na dieta | P6: % ideal | R6: Alimentos | S6: M.O. (Kg) | T6: M.S. (Kg) | U6: % P.V | V6: % da dieta | W6: Consumo total/cab | X6: Consumo total | Z6: Descrição | AB6: Resultado | AF6: Ureia pelo NNP | AH6: %MS | AK6: MS | AL6: NDT | AM6: PB | FD6: Extrato Etéreo | FE6: EE | FF6: kg/dia | FI6: 0.39 | FJ6: =FI6/$FD$3 -> 0.0021666667 | FK6: =FI6/$FI$5 -> 0.06446281 | FN6: Extrato Etéreo | FO6: EE | FP6: kg/dia | FS6: 0.48 | FT6: =FS6/FN$3 -> 0.0016 | FU6: =FS6/FS$5 -> 0.06374502 | FW6: Extrato Etéreo | FX6: EE | FY6: kg/dia | GB6: 0.48 | GC6: =GB6/FW$3 -> 0.0016 | GD6: =GB6/GB$5 -> 0.06374502 | GO6: Forragens Verdes | GP6: Capim Braquiária Brizantha | GQ6: 34.09 | GR6: 1.96 | GS6: 6.91 | GT6: 56.68 | GU6: 63.84 | GV6: 0.31 | GW6: 0.11 | GX6: 0.41 | GY6: 1.65 | GZ6: 0.02 | HA6: 0.09 | HB6: 0.07 | HC6: 3.48 | HD6: 103.19 | HF6: 26.4
B7: Peso final (kg) | H7: =G7*F7 -> 0 | J7: Matéria seca (MS) | K7: =IF(C8="","",((ROUND(IF(C10="Zebuíno",-2.1948+0.08338*C8^0.75+3.9328*C9-0.903*C9^2,IF(C11="Corte",-0.6273+0.06453*C8^0.75+3.871*C9-0.614*C9^2,-2.8836+0.08435*C8^0.75+4.5145*C9-0.9631*C9^2)),2))*L25)+(ROUND(IF(C10="Zebuíno",-2.1948+0.08338*C8^0.75+3.9328*C9-0.903*C9^2,IF(C11="Corte",-0.6273+0.06453*C8^0.75+3.871*C9-0.614*C9^2,-2.8836+0.08435*C8^0.75+4.5145*C9-0.9631*C9^2)),2))) | L7: =IF(K7="","",(ROUND(IF(C10="Zebuíno",-2.1948+0.08338*C8^0.75+3.9328*C9-0.903*C9^2,IF(C11="Corte",-0.6273+0.06453*C8^0.75+3.871*C9-0.614*C9^2,-2.8836+0.08435*C8^0.75+4.5145*C9-0.9631*C9^2)),2))*1.1) | M7: =IFERROR(T21,0) -> 0 | N7: =IF(K7="","",IF(M7>L7,"Reduzir",IF(M7<K7,"Aumentar",IF(M7=K7,"Ok",IF(M7=L7,"Ok",IF(OR(M7>=K7,M7<=L7),"Ok")))))) | O7: =IF(M7=0,"", $T$21/M7) | P7: =IF(M7=0,"",K7/ $T$21) | R7: =IF(C18="","",C18) | S7: =IF(IFERROR((K7-(C8*C19*AH20))/VLOOKUP(C18,'Formulação de suplemento'!$B$29:$C$40,2,0),0)=0,"",IFERROR((K7-(C8*C19*AH20))/VLOOKUP(C18,'Formulação de suplemento'!$B$29:$C$40,2,0),0)) | T7: =IF(R7="","",IFERROR(S7*(VLOOKUP(R7,'Formulação de suplemento'!$B$29:$W$40,2,)),0)) | U7: =IFERROR(T7/$C$8,"") | V7: =IFERROR(T7/$T$21,"") | W7: =IFERROR(X7/$C$20,"") | X7: =IFERROR(S7*$C$16*$C$20,"") | Z7: Consumo de supl. diário/cab | AB7: =IFERROR(C19*C8,"") | AF7: =IFERROR(VLOOKUP(R7,'Formulação de suplemento'!$B$56:$W$68,22,0)*T7,"") | AH7: =IF(E7="Ureia",F7,IFERROR(VLOOKUP(E7,'Formulação de suplemento'!$B$43:$C$54,2,0)*F7,"")) | AK7: =VLOOKUP(R7,B29:E40,2,0) -> #N/A | AL7: =VLOOKUP(R7,B29:E40,3,0) -> #N/A | AM7: =VLOOKUP(R7,B29:E40,4,0) -> #N/A | AV7: 3 | AW7: =AV7+1 -> 4 | AX7: =AW7+1 -> 5 | AY7: =AX7+1 -> 6 | AZ7: =AY7+1 -> 7 | BA7: =AZ7+1 -> 8 | BB7: =BA7+1 -> 9 | BC7: =BB7+1 -> 10 | BD7: =BC7+1 -> 11 | ... BM7: =BL7+1 -> 20 | FD7: Carboidratos Não Fibrosos | FE7: CNF | FF7: kg/dia | FI7: 4.4 | FJ7: =FI7/$FD$3 -> 0.024444444 | FK7: =FI7/$FI$5 -> 0.72727273 | FN7: Carboidratos Não Fibrosos | FO7: CNF | FP7: kg/dia | FS7: 5.48 | FT7: =FS7/FN$3 -> 0.018266667 | FU7: =FS7/FS$5 -> 0.72775564 | FW7: Carboidratos Não Fibrosos | FX7: CNF | FY7: kg/dia | GB7: 5.48 | GC7: =GB7/FW$3 -> 0.018266667 | GD7: =GB7/GB$5 -> 0.72775564 | GO7: Forragens Verdes | GP7: Capim Braquiária Brizantha Marandu | GQ7: 33.24 | GR7: 1.95 | GS7: 7.68 | GT7: 55.52 | GU7: 64.15 | GV7: 0.28 | GW7: 0.09 | GX7: 0.1 | GY7: 0.72 | GZ7: 0.02 | HA7: 0.03 | HB7: 0.46 | HC7: 15 | HD7: 56 | HF7: 10
B8: Peso médio (kg) | C8: =IFERROR(AVERAGE(C6:C7),"") | H8: =G8*F8 -> 0 | J8: Extrato etéreo (EE) | K8: =IF(C8="","","Não consta") | L8: =IFERROR(L7*0.063,"") | M8: =BB24/1000 -> 0 | N8: =IF(L8="","",IF(M8>L8,"Reduzir","Ok")) | O8: =IF(M8=0,"", M8/$M$7) | P8: =IF(C8="","","Não consta") | R8: =IF(F7=0,"",IF(E7="","",E7)) | S8: =IF(IF(R8="","",F7*$AB$7)=0,"",IF(R8="","",F7*$AB$7)) | T8: =IF(R8="Ureia",S8,IF(S8="","",IFERROR(S8*(VLOOKUP(R8,'Formulação de suplemento'!$B$42:$W$54,2,)),0))) | U8: =IFERROR(T8/$C$8,"") | V8: =IFERROR(T8/$T$21,"") | W8: =IFERROR(X8/$C$20,"") | X8: =IFERROR(S8*$C$16*$C$20,"") | Z8: Consumo de supl. diário no lote | AB8: =IFERROR(AB7*C20,"") | AF8: =IFERROR(VLOOKUP(R8,'Formulação de suplemento'!$B$56:$W$68,22,0)*T8,"") | AH8: =IF(E8="Ureia",F8,IFERROR(VLOOKUP(E8,'Formulação de suplemento'!$B$43:$C$54,2,0)*F8,"")) | AV8: NDT (Kg) | AW8: P.B (Kg) | AX8: Ca (g) | AY8: P (g) | AZ8: PDR (kg) | BA8: FDN (kg) | BB8: EE (g) | BC8: Mg (g) | BD8: Na (g) | BE8: K (g) | BF8: S (g) | BG8: Cu (mg) | BH8: Zn (mg) | BI8: Fe (mg) | BJ8: Mn (mg) | BK8: I (mg) | BL8: Co (mg) | BM8: Se (mg) | FD8: Fibra em Detergente Neutro | FE8: FDN | FF8: kg/dia | FG8: 1.38 | FI8: 2.38 | FJ8: =FI8/$FD$3 -> 0.013222222 | FK8: =FI8/$FI$5 -> 0.39338843 | FL8: =FG8/FH5 -> 0.25090909 | FN8: Fibra em Detergente Neutro | FO8: FDN | FP8: kg/dia | FQ8: 1.71 | FS8: 3.96 | FT8: =FS8/FN$3 -> 0.0132 | FU8: =FS8/FS$5 -> 0.52589641 | FV8: =FQ8/FR5 -> 0.24963504 | FW8: Fibra em Detergente Neutro | FX8: FDN | FY8: kg/dia | FZ8: 1.71 | GB8: 3.96 | GC8: =GB8/FW$3 -> 0.0132 | GD8: =GB8/GB$5 -> 0.52589641 | GE8: =FZ8/GA5 -> 0.24963504 | GO8: Forragens Verdes | GP8: Capim Braquiária Decumbens | GQ8: 28.49 | GR8: 1.81 | GS8: 6.74 | GT8: 55.33 | GU8: 66.38 | GV8: 0.4 | GW8: 0.1 | GX8: 0.09 | GY8: 0.94 | GZ8: 0.01 | HA8: 0.04 | HB8: 0.28 | HC8: 3.8 | HD8: 85 | HF8: 28
B9: GMD (kg/cab/dia) | H9: =G9*F9 -> 0 | J9: FDN | K9: =IFERROR(ROUND(K7*0.25,2),"") | L9: =IF(C8="","",ROUND(C8*1.32%,2)) | M9: =BA24 -> 0 | N9: =IF(K9="","",IF(M9>L9,"Reduzir",IF(M9<K9,"Aumentar",IF(M9=K9,"Ok",IF(M9=L9,"Ok",IF(OR(M9>=K9,M9<=L9),"Ok")))))) | O9: =IF(M9=0,"", M9/$M$7) | P9: =IF(M9=0,"", K9/$T$21) | R9: =IF(F8=0,"",IF(E8="","",E8)) | S9: =IF(IF(R9="","",F8*$AB$7)=0,"",IF(R9="","",F8*$AB$7)) | T9: =IF(R9="Ureia",S9,IF(S9="","",IFERROR(S9*(VLOOKUP(R9,'Formulação de suplemento'!$B$42:$W$54,2,)),0))) | U9: =IFERROR(T9/$C$8,"") | V9: =IFERROR(T9/$T$21,"") | W9: =IFERROR(X9/$C$20,"") | X9: =IFERROR(S9*$C$16*$C$20,"") | Z9: Consumo de supl. total no período | AB9: =IFERROR(AB8*C16,"") | AF9: =IFERROR(VLOOKUP(R9,'Formulação de suplemento'!$B$56:$W$68,22,0)*T9,"") | AH9: =IF(E9="Ureia",F9,IFERROR(VLOOKUP(E9,'Formulação de suplemento'!$B$43:$C$54,2,0)*F9,"")) | AK9: %EF colheita | AV9: =IFERROR($T$7*(VLOOKUP($R$7,'Formulação de suplemento'!$B$29:$W$40,AV7,0)),0) -> 0 | AW9: =IFERROR($T$7*(VLOOKUP($R$7,'Formulação de suplemento'!$B$29:$W$40,AW7,0)),0) -> 0 | AX9: =IFERROR($T$7*(VLOOKUP($R$7,'Formulação de suplemento'!$B$29:$W$40,AX7,0)*1000),0) -> 0 | AY9: =IFERROR($T$7*(VLOOKUP($R$7,'Formulação de suplemento'!$B$29:$W$40,AY7,0)*1000),0) -> 0 | AZ9: =IFERROR($T$7*(VLOOKUP($R$7,'Formulação de suplemento'!$B$29:$W$40,AZ7,0)),0) -> 0 | BA9: =IFERROR($T$7*(VLOOKUP($R$7,'Formulação de suplemento'!$B$29:$W$40,BA7,0)),0) -> 0 | BB9: =IFERROR($T$7*(VLOOKUP($R$7,'Formulação de suplemento'!$B$29:$W$40,BB7,0)*1000),0) -> 0 | BC9: =IFERROR($T$7*(VLOOKUP($R$7,'Formulação de suplemento'!$B$29:$W$40,BC7,0)*1000),0) -> 0 | BD9: =IFERROR($T$7*(VLOOKUP($R$7,'Formulação de suplemento'!$B$29:$W$40,BD7,0)*1000),0) -> 0 | BE9: =IFERROR($T$7*(VLOOKUP($R$7,'Formulação de suplemento'!$B$29:$W$40,BE7,0)*1000),0) -> 0 | BF9: =IFERROR($T$7*(VLOOKUP($R$7,'Formulação de suplemento'!$B$29:$W$40,BF7,0)*1000),0) -> 0 | BG9: =IFERROR($T$7*(VLOOKUP($R$7,'Formulação de suplemento'!$B$29:$W$40,BG7,0)),0) -> 0 | BH9: =IFERROR($T$7*(VLOOKUP($R$7,'Formulação de suplemento'!$B$29:$W$40,BH7,0)),0) -> 0 | BI9: =IFERROR($T$7*(VLOOKUP($R$7,'Formulação de suplemento'!$B$29:$W$40,BI7,0)),0) -> 0 | BJ9: =IFERROR($T$7*(VLOOKUP($R$7,'Formulação de suplemento'!$B$29:$W$40,BJ7,0)),0) -> 0 | BK9: =IFERROR($T$7*(VLOOKUP($R$7,'Formulação de suplemento'!$B$29:$W$40,BK7,0)),0) -> 0 | BL9: =IFERROR($T$7*(VLOOKUP($R$7,'Formulação de suplemento'!$B$29:$W$40,BL7,0)),0) -> 0 | BM9: =IFERROR($T$7*(VLOOKUP($R$7,'Formulação de suplemento'!$B$29:$W$40,BM7,0)),0) -> 0 | FD9: FDN Fisicamente Efetiva | FE9: FDNfe | FF9: kg/dia | FG9: 2.45 | FI9: 6.2 | FJ9: =FI9/$FD$3 -> 0.034444444 | FK9: =FI9/$FI$5 -> 1.0247934 | FN9: FDN Fisicamente Efetiva | FO9: FDNfe | FP9: kg/dia | FQ9: 2.45 | FS9: 6.2 | FT9: =FS9/FN$3 -> 0.020666667 | FU9: =FS9/FS$5 -> 0.82337317 | FW9: FDN Fisicamente Efetiva | FX9: FDNfe | FY9: kg/dia | FZ9: 2.45 | GB9: 6.2 | GC9: =GB9/FW$3 -> 0.020666667 | GD9: =GB9/GB$5 -> 0.82337317 | GO9: Forragens Verdes | GP9: Capim Braquiária Humidícola | GQ9: 28.12 | GR9: 2.45 | GS9: 7.38 | GT9: 56.61 | GU9: 71.86 | GV9: 0.38 | GW9: 0.12 | GX9: 0.2 | GY9: 1.99 | GZ9: 0.02 | HA9: 0.04 | HB9: 0.09 | HC9: 13.32 | HD9: 93.82 | HF9: 19
B10: Raça | H10: =G10*F10 -> 0 | J10: NDT | K10: =IFERROR(IF(C8="","",ROUND(BJ90/4.4,2)),"") | L10: =IFERROR(K10*1.05,"") | M10: =AV24 -> 0 | N10: =IF(K10="","",IF(M10>L10,"Reduzir",IF(M10<K10,"Aumentar",IF(M10=K10,"Ok",IF(M10=L10,"Ok",IF(OR(M10>=K10,M10<=L10),"Ok")))))) | O10: =IF(M10=0,"", M10/$M$7) | P10: =IF(M10=0,"", K10/$T$21) | R10: =IF(F9=0,"",IF(E9="","",E9)) | S10: =IF(IF(R10="","",F9*$AB$7)=0,"",IF(R10="","",F9*$AB$7)) | T10: =IF(R10="Ureia",S10,IF(S10="","",IFERROR(S10*(VLOOKUP(R10,'Formulação de suplemento'!$B$42:$W$54,2,)),0))) | U10: =IFERROR(T10/$C$8,"") | V10: =IFERROR(T10/$T$21,"") | W10: =IFERROR(X10/$C$20,"") | X10: =IFERROR(S10*$C$16*$C$20,"") | Z10: Diária do suplemento (R$/cab) | AB10: =IFERROR(AB7*H23,"") | AF10: =IFERROR(VLOOKUP(R10,'Formulação de suplemento'!$B$56:$W$68,22,0)*T10,"") | AH10: =IF(E10="Ureia",F10,IFERROR(VLOOKUP(E10,'Formulação de suplemento'!$B$43:$C$54,2,0)*F10,"")) | AK10: Contínuo | AL10: 0.3 | FD10: Teor de Amido | FE10: AMIDO | FF10: kg/dia | FG10: 2.45 | FI10: 6.2 | FJ10: =FI10/$FD$3 -> 0.034444444 | FK10: =FI10/$FI$5 -> 1.0247934 | FN10: Teor de Amido | FO10: AMIDO | FP10: kg/dia | FQ10: 2.45 | FS10: 6.2 | FT10: =FS10/FN$3 -> 0.020666667 | FU10: =FS10/FS$5 -> 0.82337317 | FW10: Teor de Amido | FX10: AMIDO | FY10: kg/dia | FZ10: 2.45 | GB10: 6.2 | GC10: =GB10/FW$3 -> 0.020666667 | GD10: =GB10/GB$5 -> 0.82337317 | GO10: Forragens Verdes | GP10: Capim Gordura | GQ10: 27.72 | GR10: 1.3 | GS10: 6.92 | GT10: 56.68 | GU10: 72.29 | GV10: 0.24 | GW10: 0.07 | GX10: 0.14 | GY10: 0.67 | GZ10: 0.02
H11: =G11*F11 -> 0 | J11: Proteína Bruta (PB) | K11: =IFERROR(ROUND(((BN58-(BN59*0.64))/0.8)+BN60,1),"") | L11: =IFERROR(K11*1.1,"") | M11: =IFERROR(AW24*1000,0) -> 0 | N11: =IF(K11="","",IF(M11>L11,"Reduzir",IF(M11<K11,"Aumentar",IF(M11=K11,"Ok",IF(M11=L11,"Ok",IF(OR(M11>=K11,M11<=L11),"Ok")))))) | O11: =IF(M11=0,"",(M11/1000)/$T$21) | P11: =IF(M11=0,"",(K11/1000)/$T$21) | R11: =IF(F10=0,"",IF(E10="","",E10)) | S11: =IF(IF(R11="","",F10*$AB$7)=0,"",IF(R11="","",F10*$AB$7)) | T11: =IF(R11="Ureia",S11,IF(S11="","",IFERROR(S11*(VLOOKUP(R11,'Formulação de suplemento'!$B$42:$W$54,2,)),0))) | U11: =IFERROR(T11/$C$8,"") | V11: =IFERROR(T11/$T$21,"") | W11: =IFERROR(X11/$C$20,"") | X11: =IFERROR(S11*$C$16*$C$20,"") | Z11: Diária total (R$/cab) | AB11: =IFERROR((AB10+C21),"") | AF11: =IFERROR(VLOOKUP(R11,'Formulação de suplemento'!$B$56:$W$68,22,0)*T11,"") | AH11: =IF(E11="Ureia",F11,IFERROR(VLOOKUP(E11,'Formulação de suplemento'!$B$43:$C$54,2,0)*F11,"")) | AK11: Alternado | AL11: 0.5 | AV11: =IFERROR($T8*(VLOOKUP($R8,'Formulação de suplemento'!$B$42:$W$54,AV$7,0)),0) -> 0 | AW11: =IFERROR($T8*(VLOOKUP($R8,'Formulação de suplemento'!$B$42:$W$54,AW$7,0)),0) -> 0 | AX11: =IFERROR($T8*(VLOOKUP($R8,'Formulação de suplemento'!$B$42:$W$54,AX$7,0)*1000),0) -> 0 | AY11: =IFERROR($T8*(VLOOKUP($R8,'Formulação de suplemento'!$B$42:$W$54,AY$7,0)*1000),0) -> 0 | AZ11: =IFERROR($T8*(VLOOKUP($R8,'Formulação de suplemento'!$B$42:$W$54,AZ$7,0)),0) -> 0 | BA11: =IFERROR($T8*(VLOOKUP($R8,'Formulação de suplemento'!$B$42:$W$54,BA$7,0)),0) -> 0 | BB11: =IFERROR($T8*(VLOOKUP($R8,'Formulação de suplemento'!$B$42:$W$54,BB$7,0)*1000),0) -> 0 | BC11: =IFERROR($T8*(VLOOKUP($R8,'Formulação de suplemento'!$B$42:$W$54,BC$7,0)*1000),0) -> 0 | BD11: =IFERROR($T8*(VLOOKUP($R8,'Formulação de suplemento'!$B$42:$W$54,BD$7,0)*1000),0) -> 0 | BE11: =IFERROR($T8*(VLOOKUP($R8,'Formulação de suplemento'!$B$42:$W$54,BE$7,0)*1000),0) -> 0 | BF11: =IFERROR($T8*(VLOOKUP($R8,'Formulação de suplemento'!$B$42:$W$54,BF$7,0)*1000),0) -> 0 | BG11: =IFERROR($T8*(VLOOKUP($R8,'Formulação de suplemento'!$B$42:$W$54,BG$7,0)),0) -> 0 | BH11: =IFERROR($T8*(VLOOKUP($R8,'Formulação de suplemento'!$B$42:$W$54,BH$7,0)),0) -> 0 | BI11: =IFERROR($T8*(VLOOKUP($R8,'Formulação de suplemento'!$B$42:$W$54,BI$7,0)),0) -> 0 | BJ11: =IFERROR($T8*(VLOOKUP($R8,'Formulação de suplemento'!$B$42:$W$54,BJ$7,0)),0) -> 0 | BK11: =IFERROR($T8*(VLOOKUP($R8,'Formulação de suplemento'!$B$42:$W$54,BK$7,0)),0) -> 0 | BL11: =IFERROR($T8*(VLOOKUP($R8,'Formulação de suplemento'!$B$42:$W$54,BL$7,0)),0) -> 0 | BM11: =IFERROR($T8*(VLOOKUP($R8,'Formulação de suplemento'!$B$42:$W$54,BM$7,0)),0) -> 0 | FD11: Nutrientes Digestíveis Totais | FE11: NDT | FF11: kg/dia | FG11: 3.99 | FH11: 3.99 | FI11: 4.19 | FJ11: =FI11/FH11 -> 1.0501253 | FN11: Nutrientes Digestíveis Totais | FO11: NDT | FP11: kg/dia | FQ11: 4.23 | FR11: 4.23 | FS11: 4.45 | FT11: =FS11/FR11 -> 1.0520095 | FW11: Nutrientes Digestíveis Totais | FX11: NDT | FY11: kg/dia | FZ11: 4.35 | GA11: 4.35 | GB11: 4.56 | GC11: =GB11/GA11 -> 1.0482759 | GO11: Forragens Verdes | GP11: Capim Massai | GQ11: 29.48 | GR11: 2.06 | GS11: 7.99 | GT11: 56.2 | GU11: 70.02
